Workbook

Sheet Income Statement
C1: ADOBE INC.
C3: Income Statement (2021-2025) | I3: Horizontal Analysis | O3: Vertical Analysis
C4: USD ($ millions) | I4: in Percentage (%) | O4: in Percentage (%)
B5: Line Items | C5: 2021 | D5: 2022 | E5: 2023 | F5: 2024 | G5: 2025 | I5: 2021 | J5: 2022 | K5: 2023 | L5: 2024 | M5: 2025 | O5: 2021 | P5: 2022 | Q5: 2023 | R5: 2024 | S5: 2025
B7: Revenue | C7: 15785 | D7: 17606 | E7: 19409 | F7: 21505 | G7: 23769 | I7: - | J7: =(D7-C7)/C7 -> 0.11536269 | K7: =(E7-D7)/D7 -> 0.10240827 | L7: =(F7-E7)/E7 -> 0.10799114 | M7: =(G7-F7)/F7 -> 0.10527784 | O7: =C7/C7 -> 1 | P7: =D7/D7 -> 1 | Q7: =E7/E7 -> 1 | R7: =F7/F7 -> 1 | S7: =G7/G7 -> 1
B8: Cost of Goods Sold | C8: 1865 | D8: 2165 | E8: 2354 | F8: 2358 | G8: 2551 | I8: - | J8: =(D8-C8)/C8 -> 0.16085791 | K8: =(E8-D8)/D8 -> 0.087297921 | L8: =(F8-E8)/E8 -> 0.0016992353 | M8: =(G8-F8)/F8 -> 0.081849025 | O8: =C8/C7 -> 0.11815014 | P8: =D8/D7 -> 0.12296944 | Q8: =E8/E7 -> 0.12128394 | R8: =F8/F7 -> 0.10964892 | S8: =G8/G7 -> 0.10732467
B9: Gross Profit | C9: =C7-C8 -> 13920 | D9: =D7-D8 -> 15441 | E9: =E7-E8 -> 17055 | F9: =F7-F8 -> 19147 | G9: =G7-G8 -> 21218 | I9: - | J9: =(D9-C9)/C9 -> 0.10926724 | K9: =(E9-D9)/D9 -> 0.10452691 | L9: =(F9-E9)/E9 -> 0.12266198 | M9: =(G9-F9)/F9 -> 0.10816316 | O9: =C9/C7 -> 0.88184986 | P9: =D9/D7 -> 0.87703056 | Q9: =E9/E7 -> 0.87871606 | R9: =F9/F7 -> 0.89035108 | S9: =G9/G7 -> 0.89267533
B11: Research and Administrative | C11: 2540 | D11: 2987 | E11: 3473 | F11: 3944 | G11: 4294 | I11: - | J11: =(D11-C11)/C11 -> 0.17598425 | K11: =(E11-D11)/D11 -> 0.16270506 | L11: =(F11-E11)/E11 -> 0.13561762 | M11: =(G11-F11)/F11 -> 0.088742394 | O11: =C11/C7 -> 0.16091226 | P11: =D11/D7 -> 0.16965807 | Q11: =E11/E7 -> 0.17893761 | R11: =F11/F7 -> 0.18339921 | S11: =G11/G7 -> 0.18065548
B12: Sales and Marketing | C12: 4321 | D12: 4968 | E12: 5351 | F12: 5764 | G12: 6488 | I12: - | J12: =(D12-C12)/C12 -> 0.14973386 | K12: =(E12-D12)/D12 -> 0.077093398 | L12: =(F12-E12)/E12 -> 0.077181835 | M12: =(G12-F12)/F12 -> 0.12560722 | O12: =C12/C7 -> 0.27374089 | P12: =D12/D7 -> 0.28217653 | Q12: =E12/E7 -> 0.27569684 | R12: =F12/F7 -> 0.26803069 | S12: =G12/G7 -> 0.27296058
B13: General and Administrative | C13: 1085 | D13: 1219 | E13: 1413 | F13: 1529 | G13: 1573 | I13: - | J13: =(D13-C13)/C13 -> 0.1235023 | K13: =(E13-D13)/D13 -> 0.15914684 | L13: =(F13-E13)/E13 -> 0.082094834 | M13: =(G13-F13)/F13 -> 0.028776978 | O13: =C13/C7 -> 0.068736142 | P13: =D13/D7 -> 0.06923776 | Q13: =E13/E7 -> 0.072801278 | R13: =F13/F7 -> 0.071099744 | S13: =G13/G7 -> 0.066178636
B14: Other Operating Expenses | C14: 172 | D14: 168 | E14: 168 | F14: 1169 | G14: 157 | I14: - | J14: =(D14-C14)/C14 -> -0.023255814 | K14: =(E14-D14)/D14 -> 0 | L14: =(F14-E14)/E14 -> 5.9583333 | M14: =(G14-F14)/F14 -> -0.86569718 | O14: =C14/C7 -> 0.010896421 | P14: =D14/D7 -> 0.0095422015 | Q14: =E14/E7 -> 0.0086557782 | R14: =F14/F7 -> 0.054359451 | S14: =G14/G7 -> 0.0066052421
B15: Operating Expenses | C15: =SUM(C11:C14) -> 8118 | D15: =SUM(D11:D14) -> 9342 | E15: =SUM(E11:E14) -> 10405 | F15: =SUM(F11:F14) -> 12406 | G15: =SUM(G11:G14) -> 12512 | I15: - | J15: =(D15-C15)/C15 -> 0.15077605 | K15: =(E15-D15)/D15 -> 0.1137872 | L15: =(F15-E15)/E15 -> 0.19231139 | M15: =(G15-F15)/F15 -> 0.0085442528 | O15: =C15/C7 -> 0.51428571 | P15: =D15/D7 -> 0.53061456 | Q15: =E15/E7 -> 0.5360915 | R15: =F15/F7 -> 0.5768891 | S15: =G15/G7 -> 0.52639993
B17: Operating Income | C17: =C9-C15 -> 5802 | D17: =D9-D15 -> 6099 | E17: =E9-E15 -> 6650 | F17: =F9-F15 -> 6741 | G17: =G9-G15 -> 8706 | I17: - | J17: =(D17-C17)/C17 -> 0.051189245 | K17: =(E17-D17)/D17 -> 0.090342679 | L17: =(F17-E17)/E17 -> 0.013684211 | M17: =(G17-F17)/F17 -> 0.29149978 | O17: =C17/C7 -> 0.36756414 | P17: =D17/D7 -> 0.34641599 | Q17: =E17/E7 -> 0.34262456 | R17: =F17/F7 -> 0.31346199 | S17: =G17/G7 -> 0.3662754
B19: Interest Expense | C19: 113 | D19: 112 | E19: 113 | F19: 169 | G19: 263 | I19: - | J19: =(D19-C19)/C19 -> -0.0088495575 | K19: =(E19-D19)/D19 -> 0.0089285714 | L19: =(F19-E19)/E19 -> 0.49557522 | M19: =(G19-F19)/F19 -> 0.55621302 | O19: =C19/C7 -> 0.007158695 | P19: =D19/D7 -> 0.0063614677 | Q19: =E19/E7 -> 0.0058220413 | R19: =F19/F7 -> 0.0078586375 | S19: =G19/G7 -> 0.011064832
B20: Other non-operating income | C20: 16 | D20: 22 | E20: 262 | F20: 359 | G20: 291 | I20: - | J20: =(D20-C20)/C20 -> 0.375 | K20: =(E20-D20)/D20 -> 10.909091 | L20: =(F20-E20)/E20 -> 0.37022901 | M20: =(G20-F20)/F20 -> -0.18941504 | O20: =C20/C7 -> 0.0010136205 | P20: =D20/D7 -> 0.001249574 | Q20: =E20/E7 -> 0.013498892 | R20: =F20/F7 -> 0.016693792 | S20: =G20/G7 -> 0.012242837
B21: Non-Operating Income | C21: =C20-C19 -> -97 | D21: =D20-D19 -> -90 | E21: =E20-E19 -> 149 | F21: =F20-F19 -> 190 | G21: =G20-G19 -> 28 | I21: - | J21: =(D21-C21)/C21 -> -0.072164948 | K21: =(E21-D21)/D21 -> -2.6555556 | L21: =(F21-E21)/E21 -> 0.27516779 | M21: =(G21-F21)/F21 -> -0.85263158 | O21: =C21/C7 -> -0.0061450744 | P21: =D21/D7 -> -0.0051118937 | Q21: =E21/E7 -> 0.0076768509 | R21: =F21/F7 -> 0.0088351546 | S21: =G21/G7 -> 0.001178005
B23: Pretax Income | C23: =C17+C21 -> 5705 | D23: =D17+D21 -> 6009 | E23: =E17+E21 -> 6799 | F23: =F17+F21 -> 6931 | G23: =G17+G21 -> 8734 | I23: - | J23: =(D23-C23)/C23 -> 0.053286591 | K23: =(E23-D23)/D23 -> 0.13146946 | L23: =(F23-E23)/E23 -> 0.01941462 | M23: =(G23-F23)/F23 -> 0.26013562 | O23: =C23/C7 -> 0.36141907 | P23: =D23/D7 -> 0.3413041 | Q23: =E23/E7 -> 0.35030141 | R23: =F23/F7 -> 0.32229714 | S23: =G23/G7 -> 0.36745341
B24: Income Tax | C24: 883 | D24: 1252 | E24: 1371 | F24: 1371 | G24: 1604 | I24: - | J24: =(D24-C24)/C24 -> 0.41789354 | K24: =(E24-D24)/D24 -> 0.095047923 | L24: =(F24-E24)/E24 -> 0 | M24: =(G24-F24)/F24 -> 0.16994894 | O24: =C24/C7 -> 0.055939183 | P24: =D24/D7 -> 0.071112121 | Q24: =E24/E7 -> 0.070637333 | R24: =F24/F7 -> 0.063752616 | S24: =G24/G7 -> 0.067482856
B25: Net Income | C25: =C23-C24 -> 4822 | D25: =D23-D24 -> 4757 | E25: =E23-E24 -> 5428 | F25: =F23-F24 -> 5560 | G25: =G23-G24 -> 7130 | I25: - | J25: =(D25-C25)/C25 -> -0.013479884 | K25: =(E25-D25)/D25 -> 0.14105529 | L25: =(F25-E25)/E25 -> 0.024318349 | M25: =(G25-F25)/F25 -> 0.2823741 | O25: =C25/C7 -> 0.30547989 | P25: =D25/D7 -> 0.27019198 | Q25: =E25/E7 -> 0.27966407 | R25: =F25/F7 -> 0.25854452 | S25: =G25/G7 -> 0.29997055
B27: Basic EPS | C27: =C25/C28 -> 10.109015 | D27: =D25/D28 -> 10.121277 | E27: =E25/E28 -> 11.877462 | F27: =F25/F28 -> 12.438479 | G27: =G25/G28 -> 16.737089
B28: Basic Share | C28: 477 | D28: 470 | E28: 457 | F28: 447 | G28: 426
B29: Diluted EPS | C29: =C25/C30 -> 10.024948 | D29: =D25/D30 -> 10.099788 | E29: =E25/E30 -> 11.825708 | F29: =F25/F30 -> 12.355556 | G29: =G25/G30 -> 16.697892
B30: Diluted Share | C30: 481 | D30: 471 | E30: 459 | F30: 450 | G30: 427
B33: EBIT | C33: =C17 -> 5802 | D33: =D17 -> 6099 | E33: =E17 -> 6650 | F33: =F17 -> 6741 | G33: =G17 -> 8706
B34: EBITDA | C34: =C17+Cashflow!C9 -> 6590 | D34: =D17+Cashflow!D9 -> 6955 | E34: =E17+Cashflow!E9 -> 7522 | F34: =F17+Cashflow!F9 -> 7598 | G34: =G17+Cashflow!G9 -> 9524

Sheet Balance Sheet
C1: ADOBE INC.
C3: Balance Sheet (2021-2025) | I3: Horizontal Analysis | O3: Vertical Analysis
C4: USD ($ millions) | I4: in Percentage (%) | O4: in Percentage (%)
B5: Line Items | C5: 2021 | D5: 2022 | E5: 2023 | F5: 2024 | G5: 2025 | I5: 2021 | J5: 2022 | K5: 2023 | L5: 2024 | M5: 2025 | O5: 2021 | P5: 2022 | Q5: 2023 | R5: 2024 | S5: 2025
B7: Cash and Cash Equivalents | C7: =INDEX(Cashflow!C8:C28,MATCH(Cashflow!$B$28,Cashflow!$B$8:$B$28,0)) -> 3844 | D7: =INDEX(Cashflow!D8:D28,MATCH(Cashflow!$B$28,Cashflow!$B$8:$B$28,0)) -> 4236 | E7: =INDEX(Cashflow!E8:E28,MATCH(Cashflow!$B$28,Cashflow!$B$8:$B$28,0)) -> 7141 | F7: =INDEX(Cashflow!F8:F28,MATCH(Cashflow!$B$28,Cashflow!$B$8:$B$28,0)) -> 7613 | G7: =INDEX(Cashflow!G8:G28,MATCH(Cashflow!$B$28,Cashflow!$B$8:$B$28,0)) -> 5431 | I7: - | J7: =(D7-C7)/C7 -> 0.10197711 | K7: =(E7-D7)/D7 -> 0.68578848 | L7: =(F7-E7)/E7 -> 0.066097185 | M7: =(G7-F7)/F7 -> -0.286615 | O7: =C7/C17 -> 0.14111083 | P7: =D7/D17 -> 0.15593595 | Q7: =E7/E17 -> 0.23979986 | R7: =F7/F17 -> 0.25183592 | S7: =G7/G17 -> 0.18412666
B8: Other Current Assets | C8: 4825 | D8: 4760 | E8: 3943 | F8: 3619 | G8: 4732 | I8: - | J8: =(D8-C8)/C8 -> -0.013471503 | K8: =(E8-D8)/D8 -> -0.17163866 | L8: =(F8-E8)/E8 -> -0.082170936 | M8: =(G8-F8)/F8 -> 0.30754352 | O8: =C8/C17 -> 0.17712272 | P8: =D8/D17 -> 0.17522547 | Q8: =E8/E17 -> 0.13240874 | R8: =F8/F17 -> 0.11971551 | S8: =G8/G17 -> 0.16042853
B9: Total Current Assets | C9: =C7+C8 -> 8669 | D9: =D7+D8 -> 8996 | E9: =E7+E8 -> 11084 | F9: =F7+F8 -> 11232 | G9: =G7+G8 -> 10163 | I9: - | J9: =(D9-C9)/C9 -> 0.037720614 | K9: =(E9-D9)/D9 -> 0.23210316 | L9: =(F9-E9)/E9 -> 0.01335258 | M9: =(G9-F9)/F9 -> -0.095174501 | O9: =C9/C17 -> 0.31823355 | P9: =D9/D17 -> 0.33116142 | Q9: =E9/E17 -> 0.3722086 | R9: =F9/F17 -> 0.37155144 | S9: =G9/G17 -> 0.34455519
B11: Property Plant and Equipment | C11: 1673 | D11: 1908 | E11: 2030 | F11: 1936 | G11: 1873 | I11: - | J11: =(D11-C11)/C11 -> 0.14046623 | K11: =(E11-D11)/D11 -> 0.0639413 | L11: =(F11-E11)/E11 -> -0.046305419 | M11: =(G11-F11)/F11 -> -0.032541322 | O11: =C11/C17 -> 0.061414779 | P11: =D11/D17 -> 0.070237438 | Q11: =E11/E17 -> 0.068168844 | R11: =F11/F17 -> 0.064042342 | S11: =G11/G17 -> 0.063500136
B12: Goodwill | C12: 12668 | D12: 12787 | E12: 12805 | F12: 12788 | G12: 12857 | I12: - | J12: =(D12-C12)/C12 -> 0.009393748 | K12: =(E12-D12)/D12 -> 0.0014076797 | L12: =(F12-E12)/E12 -> -0.0013276064 | M12: =(G12-F12)/F12 -> 0.0053956835 | O12: =C12/C17 -> 0.46503432 | P12: =D12/D17 -> 0.47071599 | Q12: =E12/E17 -> 0.43000101 | R12: =F12/F17 -> 0.42302349 | S12: =G12/G17 -> 0.43588961
B13: Other Intangible Assets | C13: 1820 | D13: 1449 | E13: 1088 | F13: 782 | G13: 495 | I13: - | J13: =(D13-C13)/C13 -> -0.20384615 | K13: =(E13-D13)/D13 -> -0.24913734 | L13: =(F13-E13)/E13 -> -0.28125 | M13: =(G13-F13)/F13 -> -0.36700767 | O13: =C13/C17 -> 0.066811057 | P13: =D13/D17 -> 0.053340696 | Q13: =E13/E17 -> 0.036535814 | R13: =F13/F17 -> 0.025868343 | S13: =G13/G17 -> 0.016781937
B14: Other Non-Current Assets | C14: 2411 | D14: 2025 | E14: 2772 | F14: 3492 | G14: 4108 | I14: - | J14: =(D14-C14)/C14 -> -0.16009954 | K14: =(E14-D14)/D14 -> 0.36888889 | L14: =(F14-E14)/E14 -> 0.25974026 | M14: =(G14-F14)/F14 -> 0.17640321 | O14: =C14/C17 -> 0.088506296 | P14: =D14/D17 -> 0.074544451 | Q14: =E14/E17 -> 0.093085732 | R14: =F14/F17 -> 0.11551439 | S14: =G14/G17 -> 0.13927312
B15: Total Non-Current Assets | C15: =SUM(C11:C14) -> 18572 | D15: =SUM(D11:D14) -> 18169 | E15: =SUM(E11:E14) -> 18695 | F15: =SUM(F11:F14) -> 18998 | G15: =SUM(G11:G14) -> 19333 | I15: - | J15: =(D15-C15)/C15 -> -0.021699332 | K15: =(E15-D15)/D15 -> 0.02895041 | L15: =(F15-E15)/E15 -> 0.016207542 | M15: =(G15-F15)/F15 -> 0.017633435 | O15: =C15/C17 -> 0.68176645 | P15: =D15/D17 -> 0.66883858 | Q15: =E15/E17 -> 0.6277914 | R15: =F15/F17 -> 0.62844856 | S15: =G15/G17 -> 0.65544481
B17: Total Assets | C17: =C9+C15 -> 27241 | D17: =D9+D15 -> 27165 | E17: =E9+E15 -> 29779 | F17: =F9+F15 -> 30230 | G17: =G9+G15 -> 29496 | I17: - | J17: =(D17-C17)/C17 -> -0.0027899123 | K17: =(E17-D17)/D17 -> 0.096226762 | L17: =(F17-E17)/E17 -> 0.015144901 | M17: =(G17-F17)/F17 -> -0.024280516 | O17: =C17/C17 -> 1 | P17: =D17/D17 -> 1 | Q17: =E17/E17 -> 1 | R17: =F17/F17 -> 1 | S17: =G17/G17 -> 1
B19: Trade payables | C19: 312 | D19: 379 | E19: 314 | F19: 361 | G19: 417 | I19: - | J19: =(D19-C19)/C19 -> 0.21474359 | K19: =(E19-D19)/D19 -> -0.17150396 | L19: =(F19-E19)/E19 -> 0.14968153 | M19: =(G19-F19)/F19 -> 0.15512465 | O19: =C19/C17 -> 0.011453324 | P19: =D19/D17 -> 0.013951776 | Q19: =E19/E17 -> 0.010544343 | R19: =F19/F17 -> 0.01194178 | S19: =G19/G17 -> 0.01413751
B20: Current Debt | C20: 0 | D20: 500 | E20: 0 | F20: 1499 | G20: 0 | I20: - | J20: - | K20: =(E20-D20)/D20 -> -1 | L20: - | M20: =(G20-F20)/F20 -> -1 | O20: =C20/C17 -> 0 | P20: =D20/D17 -> 0.018406037 | Q20: =E20/E17 -> 0 | R20: =F20/F17 -> 0.049586503 | S20: =G20/G17 -> 0
B21: Other Current Liabilities | C21: 6620 | D21: 7249 | E21: 7937 | F21: 8661 | G21: 9783 | I21: - | J21: =(D21-C21)/C21 -> 0.095015106 | K21: =(E21-D21)/D21 -> 0.094909643 | L21: =(F21-E21)/E21 -> 0.091218344 | M21: =(G21-F21)/F21 -> 0.12954624 | O21: =C21/C17 -> 0.24301604 | P21: =D21/D17 -> 0.26685073 | Q21: =E21/E17 -> 0.26653011 | R21: =F21/F17 -> 0.28650347 | S21: =G21/G17 -> 0.33167209
B22: Total Current Liabilities | C22: =SUM(C19:C21) -> 6932 | D22: =SUM(D19:D21) -> 8128 | E22: =SUM(E19:E21) -> 8251 | F22: =SUM(F19:F21) -> 10521 | G22: =SUM(G19:G21) -> 10200 | I22: - | J22: =(D22-C22)/C22 -> 0.17253318 | K22: =(E22-D22)/D22 -> 0.015132874 | L22: =(F22-E22)/E22 -> 0.27511817 | M22: =(G22-F22)/F22 -> -0.030510408 | O22: =C22/C17 -> 0.25446937 | P22: =D22/D17 -> 0.29920854 | Q22: =E22/E17 -> 0.27707445 | R22: =F22/F17 -> 0.34803176 | S22: =G22/G17 -> 0.3458096
B24: Long - term Debt | C24: 4123 | D24: 3629 | E24: 3634 | F24: 4129 | G24: 6210 | I24: - | J24: =(D24-C24)/C24 -> -0.11981567 | K24: =(E24-D24)/D24 -> 0.00137779 | L24: =(F24-E24)/E24 -> 0.13621354 | M24: =(G24-F24)/F24 -> 0.50399612 | O24: =C24/C17 -> 0.15135274 | P24: =D24/D17 -> 0.13359102 | Q24: =E24/E17 -> 0.1220323 | R24: =F24/F17 -> 0.13658617 | S24: =G24/G17 -> 0.21053702
B25: Income Taxes Payable | C25: 534 | D25: 530 | E25: 514 | F25: 548 | G25: 469 | I25: - | J25: =(D25-C25)/C25 -> -0.0074906367 | K25: =(E25-D25)/D25 -> -0.030188679 | L25: =(F25-E25)/E25 -> 0.06614786 | M25: =(G25-F25)/F25 -> -0.14416058 | O25: =C25/C17 -> 0.019602805 | P25: =D25/D17 -> 0.019510399 | Q25: =E25/E17 -> 0.017260486 | R25: =F25/F17 -> 0.018127688 | S25: =G25/G17 -> 0.015900461
B26: Other Non-Current Liabilities | C26: 855 | D26: 827 | E26: 862 | F26: 927 | G26: 994 | I26: - | J26: =(D26-C26)/C26 -> -0.032748538 | K26: =(E26-D26)/D26 -> 0.042321644 | L26: =(F26-E26)/E26 -> 0.075406032 | M26: =(G26-F26)/F26 -> 0.07227616 | O26: =C26/C17 -> 0.031386513 | P26: =D26/D17 -> 0.030443585 | Q26: =E26/E17 -> 0.028946573 | R26: =F26/F17 -> 0.030664902 | S26: =G26/G17 -> 0.033699485
B27: Total Non Current Liabilities | C27: =SUM(C23:C26) -> 5512 | D27: =SUM(D23:D26) -> 4986 | E27: =SUM(E23:E26) -> 5010 | F27: =SUM(F23:F26) -> 5604 | G27: =SUM(G23:G26) -> 7673 | I27: - | J27: =(D27-C27)/C27 -> -0.095428157 | K27: =(E27-D27)/D27 -> 0.0048134777 | L27: =(F27-E27)/E27 -> 0.11856287 | M27: =(G27-F27)/F27 -> 0.36920057 | O27: =C27/C17 -> 0.20234206 | P27: =D27/D17 -> 0.183545 | Q27: =E27/E17 -> 0.16823936 | R27: =F27/F17 -> 0.18537876 | S27: =G27/G17 -> 0.26013697
B29: Total Liabilities | C29: =C22+C27 -> 12444 | D29: =D22+D27 -> 13114 | E29: =E22+E27 -> 13261 | F29: =F22+F27 -> 16125 | G29: =G22+G27 -> 17873 | I29: - | J29: =(D29-C29)/C29 -> 0.053841209 | K29: =(E29-D29)/D29 -> 0.011209395 | L29: =(F29-E29)/E29 -> 0.21597165 | M29: =(G29-F29)/F29 -> 0.1084031 | O29: =C29/C17 -> 0.45681142 | P29: =D29/D17 -> 0.48275354 | Q29: =E29/E17 -> 0.44531381 | R29: =F29/F17 -> 0.53341052 | S29: =G29/G17 -> 0.60594657
B31: Stockholder's Equity | C31: 14797 | D31: 14051 | E31: 16518 | F31: 14105 | G31: 11623 | I31: - | J31: =(D31-C31)/C31 -> -0.050415625 | K31: =(E31-D31)/D31 -> 0.17557469 | L31: =(F31-E31)/E31 -> -0.14608306 | M31: =(G31-F31)/F31 -> -0.17596597 | O31: =C31/C17 -> 0.54318858 | P31: =D31/D17 -> 0.51724646 | Q31: =E31/E17 -> 0.55468619 | R31: =F31/F17 -> 0.46658948 | S31: =G31/G17 -> 0.39405343
B33: Total liabilities and stockholders’ equity | C33: =C29+C31 -> 27241 | D33: =D29+D31 -> 27165 | E33: =E29+E31 -> 29779 | F33: =F29+F31 -> 30230 | G33: =G29+G31 -> 29496 | I33: - | J33: =(D33-C33)/C33 -> -0.0027899123 | K33: =(E33-D33)/D33 -> 0.096226762 | L33: =(F33-E33)/E33 -> 0.015144901 | M33: =(G33-F33)/F33 -> -0.024280516 | O33: =C33/C17 -> 1 | P33: =D33/D17 -> 1 | Q33: =E33/E17 -> 1 | R33: =F33/F17 -> 1 | S33: =G33/G17 -> 1

Sheet Cashflow
C1: ADOBE INC.
C3: Cash Flow (2021 - 2025) | I3: Horizontal Analysis | O3: Vertical Analysis
C4: USD ($ millions) | I4: in Percentage (%) | O4: in Percentage (%)
B5: Line Items | C5: 2021 | D5: 2022 | E5: 2023 | F5: 2024 | G5: 2025 | I5: 2021 | J5: 2022 | K5: 2023 | L5: 2024 | M5: 2025 | O5: 2021 | P5: 2022 | Q5: 2023 | R5: 2024 | S5: 2025
B7: Cash flows from operating activities:
B8: Net income | C8: =INDEX('Income Statement'!C7:C25,MATCH("Net Income",'Income Statement'!$B$7:$B$25,0)) -> 4822 | D8: =INDEX('Income Statement'!D7:D25,MATCH("Net Income",'Income Statement'!$B$7:$B$25,0)) -> 4757 | E8: =INDEX('Income Statement'!E7:E25,MATCH("Net Income",'Income Statement'!$B$7:$B$25,0)) -> 5428 | F8: =INDEX('Income Statement'!F7:F25,MATCH("Net Income",'Income Statement'!$B$7:$B$25,0)) -> 5560 | G8: =INDEX('Income Statement'!G7:G25,MATCH("Net Income",'Income Statement'!$B$7:$B$25,0)) -> 7130 | I8: - | J8: =(D8-C8)/D8 -> -0.013664074 | K8: =(E8-D8)/E8 -> 0.12361828 | L8: =(F8-E8)/F8 -> 0.023741007 | M8: =(G8-F8)/G8 -> 0.22019635 | O8: =C8/'Income Statement'!C7 -> 0.30547989 | P8: =D8/'Income Statement'!D7 -> 0.27019198 | Q8: =E8/'Income Statement'!E7 -> 0.27966407 | R8: =F8/'Income Statement'!F7 -> 0.25854452 | S8: =G8/'Income Statement'!G7 -> 0.29997055
B9: Depreciation, amortization and accretion | C9: 788 | D9: 856 | E9: 872 | F9: 857 | G9: 818 | I9: - | J9: =(D9-C9)/D9 -> 0.079439252 | K9: =(E9-D9)/E9 -> 0.018348624 | L9: =(F9-E9)/F9 -> -0.017502917 | M9: =(G9-F9)/G9 -> -0.047677262 | O9: =C9/'Income Statement'!C7 -> 0.049920811 | P9: =D9/'Income Statement'!D7 -> 0.048619789 | Q9: =E9/'Income Statement'!E7 -> 0.044927611 | R9: =F9/'Income Statement'!F7 -> 0.039851197 | S9: =G9/'Income Statement'!G7 -> 0.034414574
B10: Stock-based compensation | C10: 1069 | D10: 1440 | E10: 1718 | F10: 1833 | G10: 1942 | I10: - | J10: =(D10-C10)/D10 -> 0.25763889 | K10: =(E10-D10)/E10 -> 0.16181607 | L10: =(F10-E10)/F10 -> 0.06273868 | M10: =(G10-F10)/G10 -> 0.056127703 | O10: =C10/'Income Statement'!C7 -> 0.067722521 | P10: =D10/'Income Statement'!D7 -> 0.081790299 | Q10: =E10/'Income Statement'!E7 -> 0.088515637 | R10: =F10/'Income Statement'!F7 -> 0.085235992 | S10: =G10/'Income Statement'!G7 -> 0.081703059
B11: Other Operating activities | C11: 551 | D11: 786 | E11: -716 | F11: -194 | G11: 141 | I11: - | J11: =(D11-C11)/D11 -> 0.29898219 | K11: =(E11-D11)/E11 -> 2.0977654 | L11: =(F11-E11)/F11 -> -2.6907216 | M11: =(G11-F11)/G11 -> 2.3758865 | O11: =C11/'Income Statement'!C7 -> 0.034906557 | P11: =D11/'Income Statement'!D7 -> 0.044643871 | Q11: =E11/'Income Statement'!E7 -> -0.036890103 | R11: =F11/'Income Statement'!F7 -> -0.0090211579 | S11: =G11/'Income Statement'!G7 -> 0.0059320964
B12: Net cash provided by operating activities | C12: =SUM(C8:C11) -> 7230 | D12: =SUM(D8:D11) -> 7839 | E12: =SUM(E8:E11) -> 7302 | F12: =SUM(F8:F11) -> 8056 | G12: =SUM(G8:G11) -> 10031 | I12: - | J12: =(D12-C12)/D12 -> 0.077688481 | K12: =(E12-D12)/E12 -> -0.073541495 | L12: =(F12-E12)/F12 -> 0.093594836 | M12: =(G12-F12)/G12 -> 0.19688964 | O12: =C12/'Income Statement'!C7 -> 0.45802978 | P12: =D12/'Income Statement'!D7 -> 0.44524594 | Q12: =E12/'Income Statement'!E7 -> 0.37621722 | R12: =F12/'Income Statement'!F7 -> 0.37461056 | S12: =G12/'Income Statement'!G7 -> 0.42202028
B14: Cash flows from investing activities:
B15: Purchases of property and equipment (CapEx) | C15: -348 | D15: -442 | E15: -360 | F15: -183 | G15: -179 | I15: - | J15: =(D15-C15)/D15 -> 0.21266968 | K15: =(E15-D15)/E15 -> -0.22777778 | L15: =(F15-E15)/F15 -> -0.96721311 | M15: =(G15-F15)/G15 -> -0.022346369 | O15: =C15/'Income Statement'!C7 -> -0.022046246 | P15: =D15/'Income Statement'!D7 -> -0.025105078 | Q15: =E15/'Income Statement'!E7 -> -0.018548096 | R15: =F15/'Income Statement'!F7 -> -0.0085096489 | S15: =G15/'Income Statement'!G7 -> -0.0075308175
B16: Other Investing Activities | C16: -3189 | D16: -128 | E16: 1136 | F16: 332 | G16: -1008 | I16: - | J16: =(D16-C16)/D16 -> -23.914062 | K16: =(E16-D16)/E16 -> 1.1126761 | L16: =(F16-E16)/F16 -> -2.4216867 | M16: =(G16-F16)/G16 -> 1.3293651 | O16: =C16/'Income Statement'!C7 -> -0.20202724 | P16: =D16/'Income Statement'!D7 -> -0.0072702488 | Q16: =E16/'Income Statement'!E7 -> 0.058529548 | R16: =F16/'Income Statement'!F7 -> 0.01543827 | S16: =G16/'Income Statement'!G7 -> -0.042408179
B17: Net cash provided by (used for) investing activities | C17: =SUM(C15:C16) -> -3537 | D17: =SUM(D15:D16) -> -570 | E17: =SUM(E15:E16) -> 776 | F17: =SUM(F15:F16) -> 149 | G17: =SUM(G15:G16) -> -1187 | I17: - | J17: =(D17-C17)/D17 -> -5.2052632 | K17: =(E17-D17)/E17 -> 1.7345361 | L17: =(F17-E17)/F17 -> -4.2080537 | M17: =(G17-F17)/G17 -> 1.1255265 | O17: =C17/'Income Statement'!C7 -> -0.22407349 | P17: =D17/'Income Statement'!D7 -> -0.032375327 | Q17: =E17/'Income Statement'!E7 -> 0.039981452 | R17: =F17/'Income Statement'!F7 -> 0.0069286213 | S17: =G17/'Income Statement'!G7 -> -0.049938996
B19: Cash flows from financing activities:
B20: Repurchases of common stock | C20: -3950 | D20: -6550 | E20: -4400 | F20: -9500 | G20: -11281 | I20: - | J20: =(D20-C20)/D20 -> 0.39694656 | K20: =(E20-D20)/E20 -> -0.48863636 | L20: =(F20-E20)/F20 -> 0.53684211 | M20: =(G20-F20)/G20 -> 0.15787607 | O20: =C20/'Income Statement'!C7 -> -0.25023757 | P20: =D20/'Income Statement'!D7 -> -0.37203226 | Q20: =E20/'Income Statement'!E7 -> -0.22669895 | R20: =F20/'Income Statement'!F7 -> -0.44175773 | S20: =G20/'Income Statement'!G7 -> -0.47460979
B21: Other Financing Activities | C21: -351 | D21: -275 | E21: -782 | F21: 1776 | G21: 221 | I21: - | J21: =(D21-C21)/D21 -> -0.27636364 | K21: =(E21-D21)/E21 -> 0.6483376 | L21: =(F21-E21)/F21 -> 1.4403153 | M21: =(G21-F21)/G21 -> -7.0361991 | O21: =C21/'Income Statement'!C7 -> -0.0222363 | P21: =D21/'Income Statement'!D7 -> -0.015619675 | Q21: =E21/'Income Statement'!E7 -> -0.040290587 | R21: =F21/'Income Statement'!F7 -> 0.082585445 | S21: =G21/'Income Statement'!G7 -> 0.0092978249
B22: Net cash used for financing activities | C22: =SUM(C20:C21) -> -4301 | D22: =SUM(D20:D21) -> -6825 | E22: =SUM(E20:E21) -> -5182 | F22: =SUM(F20:F21) -> -7724 | G22: =SUM(G20:G21) -> -11060 | I22: - | J22: =(D22-C22)/D22 -> 0.36981685 | K22: =(E22-D22)/E22 -> -0.31705905 | L22: =(F22-E22)/F22 -> 0.32910409 | M22: =(G22-F22)/G22 -> 0.30162749 | O22: =C22/'Income Statement'!C7 -> -0.27247387 | P22: =D22/'Income Statement'!D7 -> -0.38765194 | Q22: =E22/'Income Statement'!E7 -> -0.26698954 | R22: =F22/'Income Statement'!F7 -> -0.35917229 | S22: =G22/'Income Statement'!G7 -> -0.46531196
B24: Cash position:
B25: Foreign Exchange | C25: -26 | D25: -52 | E25: 9 | F25: -9 | G25: 34 | I25: - | J25: =(D25-C25)/D25 -> 0.5 | K25: =(E25-D25)/E25 -> 6.7777778 | L25: =(F25-E25)/F25 -> 2 | M25: =(G25-F25)/G25 -> 1.2647059 | O25: =C25/'Income Statement'!C7 -> -0.0016471334 | P25: =D25/'Income Statement'!D7 -> -0.0029535386 | Q25: =E25/'Income Statement'!E7 -> 0.00046370241 | R25: =F25/'Income Statement'!F7 -> -0.00041850732 | S25: =G25/'Income Statement'!G7 -> 0.0014304346
B26: Net Change in Cash | C26: =SUM(C12+C17+C22+C25) -> -634 | D26: =SUM(D12+D17+D22+D25) -> 392 | E26: =SUM(E12+E17+E22+E25) -> 2905 | F26: =SUM(F12+F17+F22+F25) -> 472 | G26: =SUM(G12+G17+G22+G25) -> -2182 | I26: - | J26: =(D26-C26)/D26 -> 2.6173469 | K26: =(E26-D26)/E26 -> 0.86506024 | L26: =(F26-E26)/F26 -> -5.154661 | M26: =(G26-F26)/G26 -> 1.2163153 | O26: =C26/'Income Statement'!C7 -> -0.040164713 | P26: =D26/'Income Statement'!D7 -> 0.022265137 | Q26: =E26/'Income Statement'!E7 -> 0.14967283 | R26: =F26/'Income Statement'!F7 -> 0.021948384 | S26: =G26/'Income Statement'!G7 -> -0.091800244
B27: Cash and cash equivalents at beginning of year | C27: 4478 | D27: 3844 | E27: 4236 | F27: 7141 | G27: 7613 | I27: - | J27: =(D27-C27)/D27 -> -0.16493236 | K27: =(E27-D27)/E27 -> 0.092540132 | L27: =(F27-E27)/F27 -> 0.40680577 | M27: =(G27-F27)/G27 -> 0.061999212 | O27: =C27/'Income Statement'!C7 -> 0.28368704 | P27: =D27/'Income Statement'!D7 -> 0.21833466 | Q27: =E27/'Income Statement'!E7 -> 0.21824927 | R27: =F27/'Income Statement'!F7 -> 0.33206231 | S27: =G27/'Income Statement'!G7 -> 0.32029114
B28: Cash and cash equivalents at end of year | C28: =SUM(C26+C27) -> 3844 | D28: =SUM(D26+D27) -> 4236 | E28: =SUM(E26+E27) -> 7141 | F28: =SUM(F26+F27) -> 7613 | G28: =SUM(G26+G27) -> 5431 | I28: - | J28: =(D28-C28)/D28 -> 0.092540132 | K28: =(E28-D28)/E28 -> 0.40680577 | L28: =(F28-E28)/F28 -> 0.061999212 | M28: =(G28-F28)/G28 -> -0.40176763 | O28: =C28/'Income Statement'!C7 -> 0.24352233 | P28: =D28/'Income Statement'!D7 -> 0.2405998 | Q28: =E28/'Income Statement'!E7 -> 0.3679221 | R28: =F28/'Income Statement'!F7 -> 0.3540107 | S28: =G28/'Income Statement'!G7 -> 0.22849089

Sheet Financial Ratios
C2: ADOBE INC.
C4: RATIO ANALYSIS
C5: USD ($ millions) or in Percentage (%) or in Ratio
B6: Ratios | C6: Ratios | D6: 2021 | E6: 2022 | F6: 2023 | G6: 2024 | H6: 2025 | I6: Analysis
B7: Profitability Ratios | C7: Revenue Growth | D7: - | E7: =('Income Statement'!D7-'Income Statement'!C7)/'Income Statement'!C7 -> 0.11536269 | F7: =('Income Statement'!E7-'Income Statement'!D7)/'Income Statement'!D7 -> 0.10240827 | G7: =('Income Statement'!F7-'Income Statement'!E7)/'Income Statement'!E7 -> 0.10799114 | H7: =('Income Statement'!G7-'Income Statement'!F7)/'Income Statement'!F7 -> 0.10527784 | I7: Revenue growth remained consistently around 10%, indicating stable business expansion.
B8: Profitability Ratios | C8: Gross Margin | D8: ='Income Statement'!C9/'Income Statement'!C7 -> 0.88184986 | E8: ='Income Statement'!D9/'Income Statement'!D7 -> 0.87703056 | F8: ='Income Statement'!E9/'Income Statement'!E7 -> 0.87871606 | G8: ='Income Statement'!F9/'Income Statement'!F7 -> 0.89035108 | H8: ='Income Statement'!G9/'Income Statement'!G7 -> 0.89267533 | I8: Gross margin stayed above 87%, reflecting strong pricing power and cost efficiency.
B9: Profitability Ratios | C9: EBITDA Margin | D9: ='Income Statement'!C34/'Income Statement'!C7 -> 0.41748495 | E9: ='Income Statement'!D34/'Income Statement'!D7 -> 0.39503578 | F9: ='Income Statement'!E34/'Income Statement'!E7 -> 0.38755217 | G9: ='Income Statement'!F34/'Income Statement'!F7 -> 0.35331318 | H9: ='Income Statement'!G34/'Income Statement'!G7 -> 0.40068997 | I9: EBITDA margin remained healthy despite fluctuations, demonstrating strong operating cash profitability.
B10: Profitability Ratios | C10: EBIT Margin | D10: ='Income Statement'!C33/'Income Statement'!C7 -> 0.36756414 | E10: ='Income Statement'!D33/'Income Statement'!D7 -> 0.34641599 | F10: ='Income Statement'!E33/'Income Statement'!E7 -> 0.34262456 | G10: ='Income Statement'!F33/'Income Statement'!F7 -> 0.31346199 | H10: ='Income Statement'!G33/'Income Statement'!G7 -> 0.3662754 | I10: EBIT margin recovered in 2025 after a temporary decline in 2024.
B11: Profitability Ratios | C11: Net Income Margin | D11: ='Income Statement'!C25/'Income Statement'!C7 -> 0.30547989 | E11: ='Income Statement'!D25/'Income Statement'!D7 -> 0.27019198 | F11: ='Income Statement'!E25/'Income Statement'!E7 -> 0.27966407 | G11: ='Income Statement'!F25/'Income Statement'!F7 -> 0.25854452 | H11: ='Income Statement'!G25/'Income Statement'!G7 -> 0.29997055 | I11: Net profit margin rebounded to 30.0% in 2025, indicating improved profitability.
B12: Profitability Ratios | C12: Operating Expense Margin | D12: ='Income Statement'!C15/'Income Statement'!C7 -> 0.51428571 | E12: ='Income Statement'!D15/'Income Statement'!D7 -> 0.53061456 | F12: ='Income Statement'!E15/'Income Statement'!E7 -> 0.5360915 | G12: ='Income Statement'!F15/'Income Statement'!F7 -> 0.5768891 | H12: ='Income Statement'!G15/'Income Statement'!G7 -> 0.52639993 | I12: Operating expenses remained relatively stable as a percentage of revenue over the period.
B13: Return Ratios | C13: Return On Assets | D13: - | E13: ='Income Statement'!D25/(('Balance Sheet'!D17+'Balance Sheet'!C17)/2) -> 0.17487042 | F13: ='Income Statement'!E25/(('Balance Sheet'!E17+'Balance Sheet'!D17)/2) -> 0.19064344 | G13: ='Income Statement'!F25/(('Balance Sheet'!F17+'Balance Sheet'!E17)/2) -> 0.18530554 | H13: ='Income Statement'!G25/(('Balance Sheet'!G17+'Balance Sheet'!F17)/2) -> 0.23875699 | I13: ROA improved steadily, reflecting more efficient utilization of company assets.
B14: Return Ratios | C14: Return On Equity | D14: - | E14: ='Income Statement'!D25/(('Balance Sheet'!D31+'Balance Sheet'!C31)/2) -> 0.32979756 | F14: ='Income Statement'!E25/(('Balance Sheet'!E31+'Balance Sheet'!D31)/2) -> 0.35513102 | G14: ='Income Statement'!F25/(('Balance Sheet'!F31+'Balance Sheet'!E31)/2) -> 0.36312576 | H14: ='Income Statement'!G25/(('Balance Sheet'!G31+'Balance Sheet'!F31)/2) -> 0.55425995 | I14: ROE increased significantly, demonstrating stronger returns generated for shareholders.
B15: Leverage Ratios | C15: Debt-To-Equity | D15: =('Balance Sheet'!C20+'Balance Sheet'!C24)/'Balance Sheet'!C31 -> 0.27863756 | E15: =('Balance Sheet'!D20+'Balance Sheet'!D24)/'Balance Sheet'!D31 -> 0.29385809 | F15: =('Balance Sheet'!E20+'Balance Sheet'!E24)/'Balance Sheet'!E31 -> 0.22000242 | G15: =('Balance Sheet'!F20+'Balance Sheet'!F24)/'Balance Sheet'!F31 -> 0.39900744 | H15: =('Balance Sheet'!G20+'Balance Sheet'!G24)/'Balance Sheet'!G31 -> 0.53428547 | I15: Debt-to-equity increased in recent years, indicating higher financial leverage.
B16: Leverage Ratios | C16: Debt-To-Assets | D16: =('Balance Sheet'!C20+'Balance Sheet'!C24)/'Balance Sheet'!C17 -> 0.15135274 | E16: =('Balance Sheet'!D20+'Balance Sheet'!D24)/'Balance Sheet'!D17 -> 0.15199706 | F16: =('Balance Sheet'!E20+'Balance Sheet'!E24)/'Balance Sheet'!E17 -> 0.1220323 | G16: =('Balance Sheet'!F20+'Balance Sheet'!F24)/'Balance Sheet'!F17 -> 0.18617268 | H16: =('Balance Sheet'!G20+'Balance Sheet'!G24)/'Balance Sheet'!G17 -> 0.21053702 | I16: Debt financed a larger portion of assets in 2024–2025, increasing leverage.
B17: Leverage Ratios | C17: Debt-To-Capital | D17: =('Balance Sheet'!C24+'Balance Sheet'!C20)/(('Balance Sheet'!C20+'Balance Sheet'!C24)+'Balance Sheet'!C31) -> 0.21791755 | E17: =('Balance Sheet'!D24+'Balance Sheet'!D20)/(('Balance Sheet'!D20+'Balance Sheet'!D24)+'Balance Sheet'!D31) -> 0.22711771 | F17: =('Balance Sheet'!E24+'Balance Sheet'!E20)/(('Balance Sheet'!E20+'Balance Sheet'!E24)+'Balance Sheet'!E31) -> 0.1803295 | G17: =('Balance Sheet'!F24+'Balance Sheet'!F20)/(('Balance Sheet'!F20+'Balance Sheet'!F24)+'Balance Sheet'!F31) -> 0.28520752 | H17: =('Balance Sheet'!G24+'Balance Sheet'!G20)/(('Balance Sheet'!G20+'Balance Sheet'!G24)+'Balance Sheet'!G31) -> 0.34823081 | I17: Debt-to-capital rose over time, reflecting greater reliance on debt financing.
B18: Leverage Ratios | C18: Net Debt | D18: ='Balance Sheet'!C20+'Balance Sheet'!C24-'Balance Sheet'!C7 -> 279 | E18: ='Balance Sheet'!D20+'Balance Sheet'!D24-'Balance Sheet'!D7 -> -107 | F18: ='Balance Sheet'!E20+'Balance Sheet'!E24-'Balance Sheet'!E7 -> -3507 | G18: ='Balance Sheet'!F20+'Balance Sheet'!F24-'Balance Sheet'!F7 -> -1985 | H18: ='Balance Sheet'!G20+'Balance Sheet'!G24-'Balance Sheet'!G7 -> 779 | I18: Net debt remained low and turned negative in several years, indicating a strong cash position.
B19: Leverage Ratios | C19: Interest Coverage | D19: ='Income Statement'!C33/'Income Statement'!C19 -> 51.345133 | E19: ='Income Statement'!D33/'Income Statement'!D19 -> 54.455357 | F19: ='Income Statement'!E33/'Income Statement'!E19 -> 58.849558 | G19: ='Income Statement'!F33/'Income Statement'!F19 -> 39.887574 | H19: ='Income Statement'!G33/'Income Statement'!G19 -> 33.102662 | I19: High interest coverage indicates excellent ability to meet interest obligations despite recent decline.
B20: Efficiency Ratios | C20: Asset Turnover | D20: - | E20: ='Income Statement'!D7/(('Balance Sheet'!D17+'Balance Sheet'!C17)/2) -> 0.64720803 | F20: ='Income Statement'!E7/(('Balance Sheet'!E17+'Balance Sheet'!D17)/2) -> 0.68168727 | G20: ='Income Statement'!F7/(('Balance Sheet'!F17+'Balance Sheet'!E17)/2) -> 0.71672582 | H20: ='Income Statement'!G7/(('Balance Sheet'!G17+'Balance Sheet'!F17)/2) -> 0.79593477 | I20: Asset turnover gradually improved, showing increased efficiency in generating revenue from assets.
B21: Efficiency Ratios | C21: Fixed Asset Turnover | D21: - | E21: ='Income Statement'!D7/(('Balance Sheet'!D11+'Balance Sheet'!C11)/2) -> 9.8330075 | F21: ='Income Statement'!E7/(('Balance Sheet'!E11+'Balance Sheet'!D11)/2) -> 9.857288 | G21: ='Income Statement'!F7/(('Balance Sheet'!F11+'Balance Sheet'!E11)/2) -> 10.84468 | H21: ='Income Statement'!G7/(('Balance Sheet'!G11+'Balance Sheet'!F11)/2) -> 12.480441 | I21: Fixed asset turnover remained strong, reflecting efficient utilization of fixed assets.
B22: Efficiency Ratios | C22: Working Capital Turnover | D22: - | E22: ='Income Statement'!D7/(('Balance Sheet'!D9-'Balance Sheet'!D22)+('Balance Sheet'!C9-'Balance Sheet'!C22)/2) -> 10.138785 | F22: ='Income Statement'!E7/(('Balance Sheet'!E9-'Balance Sheet'!E22)+('Balance Sheet'!D9-'Balance Sheet'!D22)/2) -> 5.9409244 | G22: ='Income Statement'!F7/(('Balance Sheet'!F9-'Balance Sheet'!F22)+('Balance Sheet'!E9-'Balance Sheet'!E22)/2) -> 10.108108 | H22: ='Income Statement'!G7/(('Balance Sheet'!G9-'Balance Sheet'!G22)+('Balance Sheet'!F9-'Balance Sheet'!F22)/2) -> 74.627943 | I22: Working capital turnover fluctuated significantly, suggesting changing working capital efficiency.
B23: Cash Flow Ratios | C23: Operating Cash Flow Margin | D23: =Cashflow!C12/'Income Statement'!C7 -> 0.45802978 | E23: =Cashflow!D12/'Income Statement'!D7 -> 0.44524594 | F23: =Cashflow!E12/'Income Statement'!E7 -> 0.37621722 | G23: =Cashflow!F12/'Income Statement'!F7 -> 0.37461056 | H23: =Cashflow!G12/'Income Statement'!G7 -> 0.42202028 | I23: Operating cash flow margin remained robust, demonstrating strong cash generation from operations.
B24: Cash Flow Ratios | C24: Free Cash Flow | D24: =Cashflow!C12+Cashflow!C15 -> 6882 | E24: =Cashflow!D12+Cashflow!D15 -> 7397 | F24: =Cashflow!E12+Cashflow!E15 -> 6942 | G24: =Cashflow!F12+Cashflow!F15 -> 7873 | H24: =Cashflow!G12+Cashflow!G15 -> 9852 | I24: Free cash flow increased overall, supporting investment capacity and shareholder returns.
B25: Cash Flow Ratios | C25: Free Cash Flow Margin | D25: =D24/'Income Statement'!C7 -> 0.43598353 | E25: =E24/'Income Statement'!D7 -> 0.42014086 | F25: =F24/'Income Statement'!E7 -> 0.35766912 | G25: =G24/'Income Statement'!F7 -> 0.36610091 | H25: =H24/'Income Statement'!G7 -> 0.41448946 | I25: Free cash flow margin remained consistently above 35%, reflecting healthy cash profitability.
B26: Cash Flow Ratios | C26: Cash Conversion Ratio | D26: =Cashflow!C12/'Income Statement'!C25 -> 1.4993779 | E26: =Cashflow!D12/'Income Statement'!D25 -> 1.6478873 | F26: =Cashflow!E12/'Income Statement'!E25 -> 1.3452469 | G26: =Cashflow!F12/'Income Statement'!F25 -> 1.4489209 | H26: =Cashflow!G12/'Income Statement'!G25 -> 1.4068724 | I26: Cash conversion ratio stayed above 1.0, indicating earnings translated well into operating cash flow.
B27: Cash Flow Ratios | C27: CapEX Ratio | D27: =-Cashflow!C15/Cashflow!C12 -> 0.04813278 | E27: =-Cashflow!D15/Cashflow!D12 -> 0.056384743 | F27: =-Cashflow!E15/Cashflow!E12 -> 0.049301561 | G27: =-Cashflow!F15/Cashflow!F12 -> 0.022715988 | H27: =-Cashflow!G15/Cashflow!G12 -> 0.017844681 | I27: CapEx ratio declined over time, suggesting lower capital investment relative to revenue.

Sheet Revenue Forecasting
C1: ADOBE INC.
C3: Revenue Forecasting Based On Segments (2021 - 2028)
C4: USD ($ millions)
B5: Segments | C5: 2021 | D5: 2022 | E5: 2023 | F5: 2024 | G5: 2025 | H5: 2026 | I5: 2027 | J5: 2028
B6: Digital Media | C6: 11520 | D6: 12842 | E6: 14216 | F6: 15864 | G6: 17649 | H6: =G6*(1+$G$12) -> 19664.91 | I6: =H6*(1+$G$12) -> 21911.081 | J6: =I6*(1+$G$12) -> 24413.815
B7: Digital Experience | C7: 3867 | D7: 4422 | E7: 4893 | F7: 5366 | G7: 5864 | H7: =G7*(1+$G$13) -> 6419.5415 | I7: =H7*(1+$G$13) -> 7027.7137 | J7: =I7*(1+$G$13) -> 7693.5026
B8: Publishing and Advertising | C8: 398 | D8: 342 | E8: 300 | F8: 265 | G8: 256 | H8: =G8*(1+$G$14) -> 236.7195 | I8: =H8*(1+$G$14) -> 218.89109 | J8: =I8*(1+$G$14) -> 202.40543
B10: YoY Growth Rate Assumptions
B11: Segments | C11: 2022 | D11: 2023 | E11: 2024 | F11: 2025 | G11: Avg Growth (Last 2 Yrs)
B12: Digital Media | C12: =D6/C6-1 -> 0.11475694 | D12: =E6/D6-1 -> 0.10699268 | E12: =F6/E6-1 -> 0.11592572 | F12: =G6/F6-1 -> 0.11251891 | G12: =AVERAGE(E12:F12) -> 0.11422231
B13: Digital Experience | C13: =D7/C7-1 -> 0.14352211 | D13: =E7/D7-1 -> 0.10651289 | E13: =F7/E7-1 -> 0.09666871 | F13: =G7/F7-1 -> 0.09280656 | G13: =AVERAGE(E13:F13) -> 0.094737635
B14: Publishing and Advertising | C14: =D8/C8-1 -> -0.14070352 | D14: =E8/D8-1 -> -0.12280702 | E14: =F8/E8-1 -> -0.11666667 | F14: =G8/F8-1 -> -0.033962264 | G14: =AVERAGE(E14:F14) -> -0.075314465
B16: Methodology:
B17: 2026-2028 revenue = prior year x (1 + average YoY growth rate of 2024 and 2025). Recent 2-year average used instead of full 5-year CAGR so the forecast reflects current momentum (e.g., Publishing & Advertising's decline has been decelerating, not constant).

Sheet Income Statement Forecast
C1: ADOBE INC.
C3: Income Statement Forecast (2026-2028)
C4: USD ($ millions)
B5: Line Item | C5: 2026 | D5: 2027 | E5: 2028 | G5: Assumption | H5: Basis
B7: Revenue | C7: ='Revenue Forecasting'!H6+'Revenue Forecasting'!H7+'Revenue Forecasting'!H8 -> 26321.171 | D7: ='Revenue Forecasting'!I6+'Revenue Forecasting'!I7+'Revenue Forecasting'!I8 -> 29157.686 | E7: ='Revenue Forecasting'!J6+'Revenue Forecasting'!J7+'Revenue Forecasting'!J8 -> 32309.724 | H7: Sum of 3 segment forecasts from Revenue Forecasting tab
B8: Cost of Goods Sold | C8: =C7*$G$8 -> 2855.4994 | D8: =D7*$G$8 -> 3163.2238 | E8: =E7*$G$8 -> 3505.1783 | G8: =AVERAGE('Income Statement'!F8/'Income Statement'!F7,'Income Statement'!G8/'Income Statement'!G7) -> 0.10848679 | H8: % of Revenue, avg of FY2024-FY2025 actuals
B9: Gross Profit | C9: =C7-C8 -> 23465.671 | D9: =D7-D8 -> 25994.462 | E9: =E7-E8 -> 28804.545
B11: Research and Administrative | C11: =C7*$G11 -> 4791.1727 | D11: =D7*$G11 -> 5307.4961 | E11: =E7*$G11 -> 5881.2531 | G11: =AVERAGE('Income Statement'!F11/'Income Statement'!F7,'Income Statement'!G11/'Income Statement'!G7) -> 0.18202734 | H11: % of Revenue, avg of FY2024-FY2025 actuals
B12: Sales and Marketing | C12: =C7*$G12 -> 7119.7618 | D12: =D7*$G12 -> 7887.0267 | E12: =E7*$G12 -> 8739.6392 | G12: =AVERAGE('Income Statement'!F12/'Income Statement'!F7,'Income Statement'!G12/'Income Statement'!G7) -> 0.27049563 | H12: % of Revenue, avg of FY2024-FY2025 actuals
B13: General and Administrative | C13: =C7*$G13 -> 1806.6638 | D13: =D7*$G13 -> 2001.3599 | E13: =E7*$G13 -> 2217.7133 | G13: =AVERAGE('Income Statement'!F13/'Income Statement'!F7,'Income Statement'!G13/'Income Statement'!G7) -> 0.06863919 | H13: % of Revenue, avg of FY2024-FY2025 actuals | R13: S
B14: Other Operating Expenses | C14: =C7*$G14 -> 802.33105 | D14: =D7*$G14 -> 888.79469 | E14: =E7*$G14 -> 984.8762 | G14: =AVERAGE('Income Statement'!F14/'Income Statement'!F7,'Income Statement'!G14/'Income Statement'!G7) -> 0.030482347 | H14: % of Revenue, avg of FY2024-FY2025 actuals
B15: Operating Expenses | C15: =SUM(C11:C14) -> 14519.929 | D15: =SUM(D11:D14) -> 16084.677 | E15: =SUM(E11:E14) -> 17823.482
B17: Operating Income | C17: =C9-C15 -> 8945.7419 | D17: =D9-D15 -> 9909.7846 | E17: =E9-E15 -> 10981.064
B19: Interest Expense | C19: =C7*$G$19 -> 249.04394 | D19: =D7*$G$19 -> 275.8823 | E19: =E7*$G$19 -> 305.70604 | G19: =AVERAGE('Income Statement'!F19/'Income Statement'!F7,'Income Statement'!G19/'Income Statement'!G7) -> 0.0094617349 | H19: % of Revenue, avg of FY2024-FY2025 actuals
B20: Other non-operating income | C20: =C7*$G$20 -> 380.82298 | D20: =D7*$G$20 -> 421.86258 | E20: =E7*$G$20 -> 467.46725 | G20: =AVERAGE('Income Statement'!F20/'Income Statement'!F7,'Income Statement'!G20/'Income Statement'!G7) -> 0.014468315 | H20: % of Revenue, avg of FY2024-FY2025 actuals
B21: Non-Operating Income | C21: =C20-C19 -> 131.77904 | D21: =D20-D19 -> 145.98028 | E21: =E20-E19 -> 161.76121
B23: Pretax Income | C23: =C17+C21 -> 9077.5209 | D23: =D17+D21 -> 10055.765 | E23: =E17+E21 -> 11142.825
B24: Income Tax | C24: =C23*$G$24 -> 1731.3422 | D24: =D23*$G$24 -> 1917.9212 | E24: =E23*$G$24 -> 2125.2546 | G24: =AVERAGE('Income Statement'!F24/'Income Statement'!F23,'Income Statement'!G24/'Income Statement'!G23) -> 0.19072853 | H24: Effective tax rate, avg of FY2024-FY2025 actuals
B25: Net Income | C25: =C23-C24 -> 7346.1787 | D25: =D23-D24 -> 8137.8436 | E25: =E23-E24 -> 9017.5702
B27: Basic EPS | C27: =C25/C28 -> 17.895685 | D27: =D25/D28 -> 20.602136 | E27: =E25/E28 -> 23.761713
B28: Basic Shares | C28: ='Income Statement'!G28+$G$28 -> 410.5 | D28: =C28+$G$28 -> 395 | E28: =D28+$G$28 -> 379.5 | G28: =AVERAGE('Income Statement'!F28-'Income Statement'!E28,'Income Statement'!G28-'Income Statement'!F28) -> -15.5 | H28: Avg annual share-count change, FY2024-FY2025 (buyback trend)
B29: Diluted EPS | C29: =C25/C30 -> 17.873914 | D29: =D25/D30 -> 20.602136 | E29: =E25/E30 -> 23.793061
B30: Diluted Shares | C30: ='Income Statement'!G30+$G$30 -> 411 | D30: =C30+$G$30 -> 395 | E30: =D30+$G$30 -> 379 | G30: =AVERAGE('Income Statement'!F30-'Income Statement'!E30,'Income Statement'!G30-'Income Statement'!F30) -> -16 | H30: Avg annual share-count change, FY2024-FY2025 (buyback trend)
B32: Methodology:
B33: Revenue is pulled from the Revenue Forecasting tab. All margin/expense lines are forecast as a % of revenue using the average of the last 2 actual years (FY2024-FY2025), so the model reflects recent trend rather than a 5-year blend. Share counts continue the recent annual buyback-driven decline.

Sheet Balance Sheet Forecast
C1: ADOBE INC.
C3: Balance Sheet Forecast (2026-2028)
C4: USD ($ millions)
B5: Line Item | C5: 2026 | D5: 2027 | E5: 2028 | G5: Assumption | H5: Basis
B7: Cash and Cash Equivalents | C7: ='Cash Flow Forecast'!C36 -> 5701.9937 | D7: ='Cash Flow Forecast'!D36 -> 5494.1977 | E7: ='Cash Flow Forecast'!E36 -> 5265.1656 | H7: Linked from Cash Flow Forecast ending cash (model output, not independently assumed)
B8: Other Current Assets | C8: ='Income Statement Forecast'!C7*$G$8 -> 4834.7948 | D8: ='Income Statement Forecast'!D7*$G$8 -> 5355.8191 | E8: ='Income Statement Forecast'!E7*$G$8 -> 5934.8 | G8: =AVERAGE('Balance Sheet'!F8/'Income Statement'!F7,'Balance Sheet'!G8/'Income Statement'!G7) -> 0.18368464 | H8: % of Revenue, avg of FY2024-FY2025 actuals
B9: Total Current Assets | C9: =C7+C8 -> 10536.788 | D9: =D7+D8 -> 10850.017 | E9: =E7+E8 -> 11199.966
B11: Property Plant and Equipment | C11: ='Balance Sheet'!G11-'Cash Flow Forecast'!C22-'Cash Flow Forecast'!C9 -> 1403.2209 | D11: =C11-'Cash Flow Forecast'!D22-'Cash Flow Forecast'!D9 -> 752.86334 | E11: =D11-'Cash Flow Forecast'!E22-'Cash Flow Forecast'!E9 -> -187.75841 | H11: Roll-forward: prior PP&E + CapEx - Depreciation of PP&E (both from Cash Flow Forecast)
B12: Goodwill | C12: ='Balance Sheet'!$G$12 -> 12857 | D12: ='Balance Sheet'!$G$12 -> 12857 | E12: ='Balance Sheet'!$G$12 -> 12857 | H12: Held flat at FY2025 actual (no assumed M&A)
B13: Other Intangible Assets | C13: ='Balance Sheet'!G13+$G$13 -> 198.5 | D13: =MAX(0,C13+$G$13) -> 0 | E13: =MAX(0,D13+$G$13) -> 0 | G13: =AVERAGE('Balance Sheet'!G13-'Balance Sheet'!F13,'Balance Sheet'!F13-'Balance Sheet'!E13) -> -296.5 | H13: Continues avg $ decline of FY2024-FY2025 (amortization); offset in Cash Flow Forecast row 10
B14: Other Non-Current Assets | C14: ='Income Statement Forecast'!C7*$G$14 -> 4411.5729 | D14: ='Income Statement Forecast'!D7*$G$14 -> 4886.9885 | E14: ='Income Statement Forecast'!E7*$G$14 -> 5415.2874 | G14: =AVERAGE('Balance Sheet'!F14/'Income Statement'!F7,'Balance Sheet'!G14/'Income Statement'!G7) -> 0.1676055 | H14: % of Revenue, avg of FY2024-FY2025 actuals
B15: Total Non-Current Assets | C15: =SUM(C11:C14) -> 18870.294 | D15: =SUM(D11:D14) -> 18496.852 | E15: =SUM(E11:E14) -> 18084.529
B17: Total Assets | C17: =C9+C15 -> 29407.082 | D17: =D9+D15 -> 29346.869 | E17: =E9+E15 -> 29284.495
B19: Trade payables | C19: ='Income Statement Forecast'!C7*$G$19 -> 451.81149 | D19: ='Income Statement Forecast'!D7*$G$19 -> 500.5012 | E19: ='Income Statement Forecast'!E7*$G$19 -> 554.60696 | G19: =AVERAGE('Balance Sheet'!F19/'Income Statement'!F7,'Balance Sheet'!G19/'Income Statement'!G7) -> 0.017165327 | H19: % of Revenue, avg of FY2024-FY2025 actuals
B20: Current Debt | C20: ='Balance Sheet'!$G$20 -> 0 | D20: ='Balance Sheet'!$G$20 -> 0 | E20: ='Balance Sheet'!$G$20 -> 0 | H20: Held flat at FY2025 actual (no known near-term refinancing)
B21: Other Current Liabilities | C21: ='Income Statement Forecast'!C7*$G$21 -> 10717.06 | D21: ='Income Statement Forecast'!D7*$G$21 -> 11871.99 | E21: ='Income Statement Forecast'!E7*$G$21 -> 13155.39 | G21: =AVERAGE('Balance Sheet'!F21/'Income Statement'!F7,'Balance Sheet'!G21/'Income Statement'!G7) -> 0.40716503 | H21: % of Revenue, avg of FY2024-FY2025 actuals
B22: Total Current Liabilities | C22: =SUM(C19:C21) -> 11168.872 | D22: =SUM(D19:D21) -> 12372.491 | E22: =SUM(E19:E21) -> 13709.997
B24: Long - term Debt | C24: ='Balance Sheet'!$G$24 -> 6210 | D24: ='Balance Sheet'!$G$24 -> 6210 | E24: ='Balance Sheet'!$G$24 -> 6210 | H24: Held flat at FY2025 actual (no known near-term refinancing)
B25: Income Taxes Payable | C25: ='Income Statement Forecast'!C7*$G$25 -> 595.04309 | D25: ='Income Statement Forecast'!D7*$G$25 -> 659.16823 | E25: ='Income Statement Forecast'!E7*$G$25 -> 730.42639 | G25: =AVERAGE('Balance Sheet'!F25/'Income Statement'!F7,'Balance Sheet'!G25/'Income Statement'!G7) -> 0.022607015 | H25: % of Revenue, avg of FY2024-FY2025 actuals
B26: Other Non-Current Liabilities | C26: ='Income Statement Forecast'!C7*$G$26 -> 1117.6684 | D26: ='Income Statement Forecast'!D7*$G$26 -> 1238.1145 | E26: ='Income Statement Forecast'!E7*$G$26 -> 1371.9586 | G26: =AVERAGE('Balance Sheet'!F26/'Income Statement'!F7,'Balance Sheet'!G26/'Income Statement'!G7) -> 0.042462715 | H26: % of Revenue, avg of FY2024-FY2025 actuals
B27: Total Non Current Liabilities | C27: =SUM(C23:C26) -> 7922.7115 | D27: =SUM(D23:D26) -> 8107.2827 | E27: =SUM(E23:E26) -> 8312.385
B29: Total Liabilities | C29: =C22+C27 -> 19091.583 | D29: =D22+D27 -> 20479.774 | E29: =E22+E27 -> 22022.382
B31: Stockholder's Equity | C31: ='Balance Sheet'!G31+'Income Statement Forecast'!C25+'Cash Flow Forecast'!C11+'Cash Flow Forecast'!C27+'Cash Flow Forecast'!C29 -> 10315.499 | D31: =C31+'Income Statement Forecast'!D25+'Cash Flow Forecast'!D11+'Cash Flow Forecast'!D27+'Cash Flow Forecast'!D29 -> 8867.0945 | E31: =D31+'Income Statement Forecast'!E25+'Cash Flow Forecast'!E11+'Cash Flow Forecast'!E27+'Cash Flow Forecast'!E29 -> 7262.1129 | H31: Roll-forward: prior equity + Net Income + Stock Comp + Buybacks + Other Financing
B33: Total liabilities and stockholders’ equity | C33: =C29+C31 -> 29407.082 | D33: =D29+D31 -> 29346.869 | E33: =E29+E31 -> 29284.495
B35: Balance Check (Total Assets − Total Liab. & Equity) | C35: =C17-C33 -> 0 | D35: =D17-D33 -> 0 | E35: =E17-E33 -> 0 | H35: Should equal 0 - confirms the three statements are fully linked and balanced
B37: Methodology:
B38: Every balance sheet line is forecast independently (mostly as % of revenue, avg FY2024-FY2025), except Cash, which is the linked output of the Cash Flow Forecast, and PP&E / Equity, which roll forward period-to-period. Because the Cash Flow Forecast's working-capital lines are built directly from the deltas in these balance sheet items, Total Assets ties to Total Liabilities & Equity by construction (see Balance Check row).

Sheet Cash Flow Forecast
C1: ADOBE INC.
C3: Cash Flow Forecast (2026-2028)
C4: USD ($ millions)
B5: Line Item | C5: 2026 | D5: 2027 | E5: 2028 | F5: Assumption | G5: Basis
B7: Cash flows from operating activities:
B8: Net Income | C8: ='Income Statement Forecast'!C25 -> 7346.1787 | D8: ='Income Statement Forecast'!D25 -> 8137.8436 | E8: ='Income Statement Forecast'!E25 -> 9017.5702
B9: Depreciation of PP&E | C9: ='Income Statement Forecast'!C7*$F$9-C10 -> 680.88101 | D9: ='Income Statement Forecast'!D7*$F$9-D10 -> 884.20901 | E9: ='Income Statement Forecast'!E7*$F$9-E10 -> 1199.7533 | F9: =AVERAGE(Cashflow!F9/'Income Statement'!F7,Cashflow!G9/'Income Statement'!G7) -> 0.037132886 | G9: Total D&A % of Revenue (avg FY24-25) less intangible amortization (row 10)
B10: Amortization of Intangible Assets | C10: ='Balance Sheet'!$G$13-'Balance Sheet Forecast'!C13 -> 296.5 | D10: ='Balance Sheet Forecast'!C13-'Balance Sheet Forecast'!D13 -> 198.5 | E10: ='Balance Sheet Forecast'!D13-'Balance Sheet Forecast'!E13 -> 0 | G10: Offsets the annual decline in Other Intangible Assets on Balance Sheet Forecast
B11: Stock-based compensation | C11: ='Income Statement Forecast'!C7*$F$11 -> 2197.0156 | D11: ='Income Statement Forecast'!D7*$F$11 -> 2433.7782 | E11: ='Income Statement Forecast'!E7*$F$11 -> 2696.8773 | F11: =AVERAGE(Cashflow!F10/'Income Statement'!F7,Cashflow!G10/'Income Statement'!G7) -> 0.083469525 | G11: % of Revenue, avg of FY2024-FY2025 actuals
B12: Other Operating activities | C12: 0 | D12: 0 | E12: 0 | G12: Assumed to normalize to zero (historically volatile, non-recurring item)
B13: Change in Other Current Assets | C13: =-('Balance Sheet Forecast'!C8-'Balance Sheet'!G8) -> -102.7948 | D13: =-('Balance Sheet Forecast'!D8-'Balance Sheet Forecast'!C8) -> -521.02429 | E13: =-('Balance Sheet Forecast'!E8-'Balance Sheet Forecast'!D8) -> -578.98092 | G13: Increase in asset = use of cash (derived from Balance Sheet Forecast)
B14: Change in Trade Payables | C14: ='Balance Sheet Forecast'!C19-'Balance Sheet'!G19 -> 34.811493 | D14: ='Balance Sheet Forecast'!D19-'Balance Sheet Forecast'!C19 -> 48.689711 | E14: ='Balance Sheet Forecast'!E19-'Balance Sheet Forecast'!D19 -> 54.105757 | G14: Increase in liability = source of cash
B15: Change in Other Current Liabilities | C15: ='Balance Sheet Forecast'!C21-'Balance Sheet'!G21 -> 934.06033 | D15: ='Balance Sheet Forecast'!D21-'Balance Sheet Forecast'!C21 -> 1154.9298 | E15: ='Balance Sheet Forecast'!E21-'Balance Sheet Forecast'!D21 -> 1283.3995 | G15: Increase in liability = source of cash
B16: Change in Income Taxes Payable | C16: ='Balance Sheet Forecast'!C25-'Balance Sheet'!G25 -> 126.04309 | D16: ='Balance Sheet Forecast'!D25-'Balance Sheet Forecast'!C25 -> 64.125142 | E16: ='Balance Sheet Forecast'!E25-'Balance Sheet Forecast'!D25 -> 71.258162 | G16: Increase in liability = source of cash
B17: Change in Other Non-Current Assets | C17: =-('Balance Sheet Forecast'!C14-'Balance Sheet'!G14) -> -303.57294 | D17: =-('Balance Sheet Forecast'!D14-'Balance Sheet Forecast'!C14) -> -475.41556 | E17: =-('Balance Sheet Forecast'!E14-'Balance Sheet Forecast'!D14) -> -528.29885 | G17: Increase in asset = use of cash
B18: Change in Other Non-Current Liabilities | C18: ='Balance Sheet Forecast'!C26-'Balance Sheet'!G26 -> 123.66837 | D18: ='Balance Sheet Forecast'!D26-'Balance Sheet Forecast'!C26 -> 120.44614 | E18: ='Balance Sheet Forecast'!E26-'Balance Sheet Forecast'!D26 -> 133.84408 | G18: Increase in liability = source of cash
B19: Net cash provided by operating activities | C19: =SUM(C8:C18) -> 11332.791 | D19: =SUM(D8:D18) -> 12046.082 | E19: =SUM(E8:E18) -> 13349.528
B21: Cash flows from investing activities:
B22: Purchases of property and equipment (CapEx) | C22: ='Income Statement Forecast'!C7*$F$22 -> -211.10193 | D22: ='Income Statement Forecast'!D7*$F$22 -> -233.85144 | E22: ='Income Statement Forecast'!E7*$F$22 -> -259.13152 | F22: =AVERAGE(Cashflow!F15/'Income Statement'!F7,Cashflow!G15/'Income Statement'!G7) -> -0.0080202332 | G22: % of Revenue, avg of FY2024-FY2025 actuals (negative = cash outflow)
B23: Other Investing Activities | C23: 0 | D23: 0 | E23: 0 | G23: Assumed to normalize to zero (historically volatile, non-recurring item)
B24: Net cash provided by (used for) investing activities | C24: =SUM(C22:C23) -> -211.10193 | D24: =SUM(D22:D23) -> -233.85144 | E24: =SUM(E22:E23) -> -259.13152
B26: Cash flows from financing activities:
B27: Repurchases of common stock | C27: ='Income Statement Forecast'!C7*$F$27 -> -12059.933 | D27: ='Income Statement Forecast'!D7*$F$27 -> -13359.578 | E27: ='Income Statement Forecast'!E7*$F$27 -> -14803.791 | F27: =AVERAGE(Cashflow!F20/'Income Statement'!F7,Cashflow!G20/'Income Statement'!G7) -> -0.45818376 | G27: % of Revenue, avg of FY2024-FY2025 actuals (negative = cash outflow)
B28: Net Debt Issuance / (Repayment) | C28: =('Balance Sheet Forecast'!C20-'Balance Sheet'!G20)+('Balance Sheet Forecast'!C24-'Balance Sheet'!G24) -> 0 | D28: =('Balance Sheet Forecast'!D20-'Balance Sheet Forecast'!C20)+('Balance Sheet Forecast'!D24-'Balance Sheet Forecast'!C24) -> 0 | E28: =('Balance Sheet Forecast'!E20-'Balance Sheet Forecast'!D20)+('Balance Sheet Forecast'!E24-'Balance Sheet Forecast'!D24) -> 0 | G28: Change in Current + Long-term Debt (both held flat in Balance Sheet Forecast)
B29: Other Financing Activities | C29: ='Income Statement Forecast'!C7*$F$29 -> 1209.2376 | D29: ='Income Statement Forecast'!D7*$F$29 -> 1339.5518 | E29: ='Income Statement Forecast'!E7*$F$29 -> 1484.3615 | F29: =AVERAGE(Cashflow!F21/'Income Statement'!F7,Cashflow!G21/'Income Statement'!G7) -> 0.045941635 | G29: % of Revenue, avg of FY2024-FY2025 actuals
B30: Net cash used for financing activities | C30: =SUM(C27:C29) -> -10850.695 | D30: =SUM(D27:D29) -> -12020.026 | E30: =SUM(E27:E29) -> -13319.429
B32: Cash position:
B33: Foreign Exchange | C33: 0 | D33: 0 | E33: 0 | G33: Assumed immaterial / zero
B34: Net Change in Cash | C34: =C19+C24+C30+C33 -> 270.99368 | D34: =D19+D24+D30+D33 -> -207.79595 | E34: =E19+E24+E30+E33 -> -229.03208
B35: Cash and cash equivalents at beginning of year | C35: 5431 | D35: =C36 -> 5701.9937 | E35: =D36 -> 5494.1977 | G35: FY2025 actual ending cash (Balance Sheet / Cash Flow tab) — hardcoded to avoid a pre-existing broken XLOOKUP chain in those tabs
B36: Cash and cash equivalents at end of year | C36: =C34+C35 -> 5701.9937 | D36: =D34+D35 -> 5494.1977 | E36: =E34+E35 -> 5265.1656
B38: Methodology:
B39: Built with the indirect method, fully linked to the Balance Sheet Forecast: every working-capital line here is the year-over-year change in the corresponding Balance Sheet Forecast item, so operating cash flow reflects real balance-sheet movement rather than a standalone assumption. PP&E depreciation and CapEx tie directly into the PP&E roll-forward on the Balance Sheet Forecast; ending cash here is the figure that appears as Cash on the Balance Sheet Forecast.

Sheet Power BI Dashboard
B1: Category | C1: Ratios | D1: Year | E1: Value
B2: Profitability | C2: Revenue Growth | D2: 2021 | E2: ='Financial Ratios'!D7 -> -
B3: Profitability | C3: Revenue Growth | D3: 2022 | E3: ='Financial Ratios'!E7 -> 0.11536269
B4: Profitability | C4: Revenue Growth | D4: 2023 | E4: ='Financial Ratios'!F7 -> 0.10240827
B5: Profitability | C5: Revenue Growth | D5: 2024 | E5: ='Financial Ratios'!G7 -> 0.10799114
B6: Profitability | C6: Revenue Growth | D6: 2025 | E6: ='Financial Ratios'!H7 -> 0.10527784
B7: Profitability | C7: Gross Margin | D7: 2021 | E7: ='Financial Ratios'!D8 -> 0.88184986
B8: Profitability | C8: Gross Margin | D8: 2022 | E8: ='Financial Ratios'!E8 -> 0.87703056
B9: Profitability | C9: Gross Margin | D9: 2023 | E9: ='Financial Ratios'!F8 -> 0.87871606
B10: Profitability | C10: Gross Margin | D10: 2024 | E10: ='Financial Ratios'!G8 -> 0.89035108
B11: Profitability | C11: Gross Margin | D11: 2025 | E11: ='Financial Ratios'!H8 -> 0.89267533
B12: Profitability | C12: EBITDA Margin | D12: 2021 | E12: ='Financial Ratios'!D9 -> 0.41748495
B13: Profitability | C13: EBITDA Margin | D13: 2022 | E13: ='Financial Ratios'!E9 -> 0.39503578
B14: Profitability | C14: EBITDA Margin | D14: 2023 | E14: ='Financial Ratios'!F9 -> 0.38755217
B15: Profitability | C15: EBITDA Margin | D15: 2024 | E15: ='Financial Ratios'!G9 -> 0.35331318
B16: Profitability | C16: EBITDA Margin | D16: 2025 | E16: ='Financial Ratios'!H9 -> 0.40068997
B17: Profitability | C17: EBIT Margin | D17: 2021 | E17: ='Financial Ratios'!D10 -> 0.36756414
B18: Profitability | C18: EBIT Margin | D18: 2022 | E18: ='Financial Ratios'!E10 -> 0.34641599
B19: Profitability | C19: EBIT Margin | D19: 2023 | E19: ='Financial Ratios'!F10 -> 0.34262456
B20: Profitability | C20: EBIT Margin | D20: 2024 | E20: ='Financial Ratios'!G10 -> 0.31346199
B21: Profitability | C21: EBIT Margin | D21: 2025 | E21: ='Financial Ratios'!H10 -> 0.3662754
B22: Profitability | C22: Net Income Margin | D22: 2021 | E22: ='Financial Ratios'!D11 -> 0.30547989
B23: Profitability | C23: Net Income Margin | D23: 2022 | E23: ='Financial Ratios'!E11 -> 0.27019198
B24: Profitability | C24: Net Income Margin | D24: 2023 | E24: ='Financial Ratios'!F11 -> 0.27966407
B25: Profitability | C25: Net Income Margin | D25: 2024 | E25: ='Financial Ratios'!G11 -> 0.25854452
B26: Profitability | C26: Net Income Margin | D26: 2025 | E26: ='Financial Ratios'!H11 -> 0.29997055
B27: Profitability | C27: Operating Expense Margin | D27: 2021 | E27: ='Financial Ratios'!D12 -> 0.51428571
B28: Profitability | C28: Operating Expense Margin | D28: 2022 | E28: ='Financial Ratios'!E12 -> 0.53061456
B29: Profitability | C29: Operating Expense Margin | D29: 2023 | E29: ='Financial Ratios'!F12 -> 0.5360915
B30: Profitability | C30: Operating Expense Margin | D30: 2024 | E30: ='Financial Ratios'!G12 -> 0.5768891
B31: Profitability | C31: Operating Expense Margin | D31: 2025 | E31: ='Financial Ratios'!H12 -> 0.52639993
B32: Return Ratios | C32: Return On Assets | D32: 2021 | E32: ='Financial Ratios'!D13 -> -
B33: Return Ratios | C33: Return On Assets | D33: 2022 | E33: ='Financial Ratios'!E13 -> 0.17487042
B34: Return Ratios | C34: Return On Assets | D34: 2023 | E34: ='Financial Ratios'!F13 -> 0.19064344
B35: Return Ratios | C35: Return On Assets | D35: 2024 | E35: ='Financial Ratios'!G13 -> 0.18530554
B36: Return Ratios | C36: Return On Assets | D36: 2025 | E36: ='Financial Ratios'!H13 -> 0.23875699
B37: Return Ratios | C37: Return On Equity | D37: 2021 | E37: ='Financial Ratios'!D14 -> -
B38: Return Ratios | C38: Return On Equity | D38: 2022 | E38: ='Financial Ratios'!E14 -> 0.32979756
B39: Return Ratios | C39: Return On Equity | D39: 2023 | E39: ='Financial Ratios'!F14 -> 0.35513102
B40: Return Ratios | C40: Return On Equity | D40: 2024 | E40: ='Financial Ratios'!G14 -> 0.36312576
...
