Workbook

Sheet SBI IS
B1: State Bank Of India
B3: Income Statement (2024-2026)
B4: INR ( Rupees in Crores)
B5: Line Items | C5: 2024 | D5: 2025 | E5: 2026
B7: Interest Earned | C7: 439188.51 | D7: 490312.7 | E7: 514932.59
B8: Interest Expense | C8: 259736.05 | D8: 300943.34 | E8: 315004.81
B9: Net Interest Income | C9: =C7-C8 -> 179452.46 | D9: =D7-D8 -> 189369.36 | E9: =E7-E8 -> 199927.78
B10: Other Income | C10: 155386.39 | D10: 173030.62 | E10: 197710.94
B11: Net Revenue | C11: =C9+C10 -> 334838.86 | D11: =D9+D10 -> 362399.98 | E11: =E9+E10 -> 397638.72
B13: Operating expenses | C13: 235893.84 | D13: 236573.52 | E13: 262650.45
B14: Operating Income | C14: =C11-C13 -> 98945.018 | D14: =D11-D13 -> 125826.46 | E14: =E11-E13 -> 134988.27
B16: Provisions and contingencies (ex-tax) | C16: 7704.98 | D16: 19461.17 | E16: 20960.29
B17: Net Profit Before Taxation | C17: =C14-C16 -> 91240.038 | D17: =D14-D16 -> 106365.29 | E17: =E14-E16 -> 114027.98
B18: Taxation | C18: 23101.78 | D18: 27348.14 | E18: 28859.51
B19: Net Profit After taxation | C19: =C17-C18 -> 68138.258 | D19: =D17-D18 -> 79017.154 | E19: =E17-E18 -> 85168.472
B20: Share in Profit of Associates | C20: 1405.1543 | D20: 1505.4709 | E20: 1497.199
B21: Less: Minority Interest | C21: 2458.7491 | D21: 2961.2882 | E21: 3366.8852
B22: Net Profit | C22: =C19+C20-C21 -> 67084.663 | D22: =D19+D20-D21 -> 77561.336 | E22: =E19+E20-E21 -> 83298.786
B24: Basic EPS | C24: =(C22)/C25 -> 75.168157 | D24: =(D22)/D25 -> 86.907186 | E24: =(E22)/E25 -> 91.160855
B25: Basic Shares | C25: 892.46119 | D25: 892.46171 | E25: 913.75608
B26: Diluted EPS | C26: =(C22)/C27 -> 75.168157 | D26: =(D22)/D27 -> 86.907186 | E26: =(E22)/E27 -> 91.160855
B27: Diluted Shares | C27: 892.46119 | D27: 892.46171 | E27: 913.75608

Sheet SBI BS
B1: State Bank Of India
B3: Balance Sheet (2024-2026)
B4: INR ( Rupees in Crores)
B5: Line Items | C5: 2024 | D5: 2025 | E5: 2026
B7: Capital and Liabilities
B8: Capital | C8: 892.4612 | D8: 892.462 | E8: 923.0618
B9: Reserves & Surplus | C9: 414046.71 | D9: 486144.3 | E9: 595207.81
B10: Minority Interest & Other Equity | C10: 15617.962 | D10: 18025.839 | E10: 18768.282
B12: Deposits | C12: 4966537.5 | D12: 5439898 | E12: 6043097.1
B13: Borrowings | C13: 639609.5 | D13: 610857.24 | E13: 777302.15
B14: Other Liabilities and Provisions | C14: 697074.68 | D14: 758367.48 | E14: 886270.15
B15: Total Capital and Liabilities | C15: =SUM(C8:C14) -> 6733778.8 | D15: =SUM(D8:D14) -> 7314185.3 | E15: =SUM(E8:E14) -> 8321568.6
B17: Assets
B18: Cash and Balances with Reserve Bank of India | C18: 225356.34 | D18: 227485.16 | E18: 268681.74
B19: Balances with Banks and Money at Call & Short Notice | C19: 101215.97 | D19: 130447.79 | E19: 133161.47
B20: Investments | C20: 2110548.2 | D20: 2205601.1 | E20: 2359502.2
B21: Advances | C21: 3784272.7 | D21: 4250830.7 | E21: 4978013.2
B22: Fixed Assets | C22: 44708.177 | D22: 46337.695 | E22: 57152.101
B23: Other Assets | C23: 467677.42 | D23: 453482.86 | E23: 525057.89
B24: Total Assets | C24: =SUM(C17:C23) -> 6733778.8 | D24: =SUM(D17:D23) -> 7314185.3 | E24: =SUM(E17:E23) -> 8321568.6
B26: CET 1 Capital | C26: 333705.96 | D26: 394378.8 | E26: 486848.03
B27: Tier 1 Capital | C27: 384177.36 | D27: 441970.13 | E27: 527992.31
B28: Tier 2 Capital | C28: 75846.02 | D28: 78091.97 | E28: 82087.77
B29: Total Capital (Tier1 + Tier 2) | C29: =C27+C28 -> 460023.38 | D29: =D27+D28 -> 520062.1 | E29: =E27+E28 -> 610080.08
B30: Risk-Weighted Assets | C30: 3222358.3 | D30: 3649286.5 | E30: 3962184.6
B32: Total Employee | C32: 232296 | D32: 236226 | E32: 245131

Sheet SBI CF
B1: State Bank Of India
B3: Cash Flow (2024-2026)
B4: INR ( Rupees in Crores)
B5: Line Items | C5: 2024 | D5: 2025 | E5: 2026
B7: Cash Flow From Operating Activites
B8: Net Profit/(Loss) before taxes (including share in profit from associates and net of minority interest) | C8: ='SBI IS'!C17+'SBI IS'!C20-'SBI IS'!C21 -> 90186.443 | D8: ='SBI IS'!D17+'SBI IS'!D20-'SBI IS'!D21 -> 104909.48 | E8: ='SBI IS'!E17+'SBI IS'!E20-'SBI IS'!E21 -> 112158.3
B9: Depreciation on Fixed Assets | C9: 3849.1245 | D9: 3991.4767 | E9: 4829.7185
B10: Other Operating Activities | C10: 11088.191 | D10: 20360.15 | E10: 28893.687
B11: Tax refund / (Taxes paid) | C11: -31268.268 | D11: -33761.445 | E11: -36322.966
B12: Change in Net Working Capital | C12: -52223.064 | D12: -50015.65 | E12: -71461.347
B14: Total Cash Flow From Operating Activites | C14: =C8+C9+C1+C10+C11+C12 -> 21632.427 | D14: =D8+D9+D1+D10+D11+D12 -> 45484.008 | E14: =E8+E9+E1+E10+E11+E12 -> 38097.388
B16: Cash Flow From Investing Activites
B17: Purchase of Investments | C17: -82.161 | D17: - | E17: -108.2683
B18: Sale Of Investments | C18: - | D18: -6.519 | E18: 7779.4109
B19: Purchase of Fixed Assets | C19: -4175.1262 | D19: -5637.2241 | E19: -8362.9582
B20: Income from Investments in Associates | C20: 5.5719 | D20: 9.0009 | E20: 0.9299
B21: Total Cash Flow From Investing Activites | C21: =SUM(C17:C20) -> -4251.7153 | D21: =SUM(D17:D20) -> -5634.7422 | E21: =SUM(E17:E20) -> -690.8857
B23: Cash Flow From Financing Activites
B24: Dividend paid | C24: -10084.811 | D24: -12226.718 | E24: -14190.146
B25: Other Financing Activities | C25: 188.53 | D25: 1489.9243 | E25: 10763.008
B26: Total Cash Flow From Financing Activites | C26: =SUM(C24:C25) -> -9896.2815 | D26: =SUM(D24:D25) -> -10736.794 | E26: =SUM(E24:E25) -> -3427.1374
B28: Effect of fluctuation in foreign currency translation reserve | C28: 775.9581 | D28: 2248.1669 | E28: 9930.8997
B29: Net Change in Cash | C29: =C14+C21+C26+C28 -> 8260.3878 | D29: =D14+D21+D26+D28 -> 31360.639 | E29: =E14+E21+E26+E28 -> 43910.265
B31: Cash and cash equivalents at the beginning of the year | C31: 318311.91 | D31: ='SBI BS'!C18+'SBI BS'!C19 -> 326572.3 | E31: ='SBI BS'!D18+'SBI BS'!D19 -> 357932.94
B32: Cash and cash equivalents at the end of the year | C32: =C29+C31 -> 326572.3 | D32: =D31+D29 -> 357932.94 | E32: =E31+E29 -> 401843.21

Sheet SBI IS Forecasting
B1: State Bank Of India
B3: Income Statement (2024-2026)
B4: INR ( Rupees in Crores)
B5: Line Items | C5: 2024 | D5: 2025 | E5: 2026 | F5: 2027 | G5: 2028 | H5: 2029
B7: Interest Earned | C7: 439188.51 | D7: 490312.7 | E7: 514932.59 | F7: =E7*(1+$C$31) -> 557831.28 | G7: =F7*(1+$C$31) -> 604303.83 | H7: =G7*(1+$C$31) -> 654647.97
B8: Interest Expense | C8: 259736.05 | D8: 300943.34 | E8: 315004.81 | F8: =E8*(1+$C$32) -> 347351.91 | G8: =F8*(1+$C$32) -> 383020.66 | H8: =G8*(1+$C$32) -> 422352.14
B9: Net Interest Income | C9: =C7-C8 -> 179452.46 | D9: =D7-D8 -> 189369.36 | E9: =E7-E8 -> 199927.78 | F9: =F7-F8 -> 210479.37 | G9: =G7-G8 -> 221283.17 | H9: =H7-H8 -> 232295.83
B10: Other Income | C10: 155386.39 | D10: 173030.62 | E10: 197710.94 | F10: =E10*(1+$C$33) -> 223036.35 | G10: =F10*(1+$C$33) -> 251605.77 | H10: =G10*(1+$C$33) -> 283834.73
B11: Net Revenue | C11: =C9+C10 -> 334838.86 | D11: =D9+D10 -> 362399.98 | E11: =E9+E10 -> 397638.72 | F11: =F9+F10 -> 433515.72 | G11: =G9+G10 -> 472888.93 | H11: =H9+H10 -> 516130.55
B13: Operating expenses | C13: 235893.84 | D13: 236573.52 | E13: 262650.45 | F13: =E13*(1+$C$34) -> 277504.5 | G13: =F13*(1+$C$34) -> 293198.61 | H13: =G13*(1+$C$34) -> 309780.3
B14: Operating Income | C14: =C11-C13 -> 98945.018 | D14: =D11-D13 -> 125826.46 | E14: =E11-E13 -> 134988.27 | F14: =F11-F13 -> 156011.22 | G14: =G11-G13 -> 179690.32 | H14: =H11-H13 -> 206350.26
B16: Provisions and contingencies (ex-tax) | C16: 7704.98 | D16: 19461.17 | E16: 20960.29 | F16: =$C$35*'SBI BS Forecasting'!F21 -> 20605.677 | G16: =$C$35*'SBI BS Forecasting'!G21 -> 23638.39 | H16: =$C$35*'SBI BS Forecasting'!H21 -> 27117.453
B17: Net Profit Before Taxation | C17: =C14-C16 -> 91240.038 | D17: =D14-D16 -> 106365.29 | E17: =E14-E16 -> 114027.98 | F17: =F14-F16 -> 135405.54 | G17: =G14-G16 -> 156051.93 | H17: =H14-H16 -> 179232.81
B18: Taxation | C18: 23101.78 | D18: 27348.14 | E18: 28859.51 | F18: =F17*$C$36 -> 34456.402 | G18: =G17*$C$36 -> 39710.253 | H18: =H17*$C$36 -> 45609.048
B19: Net Profit After taxation | C19: =C17-C18 -> 68138.258 | D19: =D17-D18 -> 79017.154 | E19: =E17-E18 -> 85168.472 | F19: =F17-F18 -> 100949.14 | G19: =G17-G18 -> 116341.68 | H19: =H17-H18 -> 133623.76
B20: Share in Profit of Associates | C20: 1405.1543 | D20: 1505.4709 | E20: 1497.199 | F20: =E20*(1+$C$37) -> 1546.5297 | G20: =F20*(1+$C$37) -> 1597.4858 | H20: =G20*(1+$C$37) -> 1650.1208
B21: Less: Minority Interest | C21: 2458.7491 | D21: 2961.2882 | E21: 3366.8852 | F21: =E21*(1+$C$38) -> 3941.5359 | G21: =F21*(1+$C$38) -> 4614.2665 | H21: =G21*(1+$C$38) -> 5401.8169
B22: Net Profit | C22: =C19+C20-C21 -> 67084.663 | D22: =D19+D20-D21 -> 77561.336 | E22: =E19+E20-E21 -> 83298.786 | F22: =F19+F20-F21 -> 98554.131 | G22: =G19+G20-G21 -> 113324.9 | H22: =H19+H20-H21 -> 129872.06
B24: Basic EPS | C24: =(C22)/C25 -> 75.168157 | D24: =(D22)/D25 -> 86.907186 | E24: =(E22)/E25 -> 91.160855 | F24: =(F22)/F25 -> 106.58446 | G24: =(G22)/G25 -> 121.11384 | H24: =(H22)/H25 -> 137.1619
B25: Basic Shares | C25: 892.46119 | D25: 892.46171 | E25: 913.75608 | F25: =E25*(1+$C$39) -> 924.65757 | G25: =F25*(1+$C$39) -> 935.68913 | H25: =G25*(1+$C$39) -> 946.85229
B26: Diluted EPS | C26: =(C22)/C27 -> 75.168157 | D26: =(D22)/D27 -> 86.907186 | E26: =(E22)/E27 -> 91.160855 | F26: =(F22)/F27 -> 106.58446 | G26: =(G22)/G27 -> 121.11384 | H26: =(H22)/H27 -> 137.1619
B27: Diluted Shares | C27: 892.46119 | D27: 892.46171 | E27: 913.75608 | F27: =F25 -> 924.65757 | G27: =G25 -> 935.68913 | H27: =H25 -> 946.85229
B29: Key Forecast Assumptions (applied 2027-2029)
B30: Driver / Assumption | C30: Value | D30: Basis / Note
B31: Interest Earned growth | C31: =AVERAGE(D7/C7-1,E7/D7-1) -> 0.083309326 | D31: Average YoY growth, FY2024-FY2026
B32: Interest Expense growth | C32: =AVERAGE(D8/C8-1,E8/D8-1) -> 0.10268764 | D32: Average YoY growth, FY2024-FY2026
B33: Other Income growth | C33: =AVERAGE(D10/C10-1,E10/D10-1) -> 0.12809311 | D33: Average YoY growth, FY2024-FY2026
B34: Operating Expenses growth | C34: =AVERAGE(D13/C13-1,E13/D13-1) -> 0.056554445 | D34: Average YoY growth, FY2024-FY2026
B35: Provisions (% of Advances) | C35: =AVERAGE(C16/'SBI BS Forecasting'!C21,D16/'SBI BS Forecasting'!D21,E16/'SBI BS Forecasting'!E21) -> 0.0036082768 | D35: Avg Provisions/Advances FY2024-26; applied to 'SBI BS Forecasting' Advances
B36: Effective Tax Rate | C36: =AVERAGE(C18/C17,D18/D17,E18/E17) -> 0.25446819 | D36: Average effective tax rate (Tax/PBT), FY2024-FY2026
B37: Share in Profit of Associates growth | C37: =AVERAGE(D20/C20-1,E20/D20-1) -> 0.032948658 | D37: Average YoY growth, FY2024-FY2026
B38: Minority Interest growth | C38: =AVERAGE(D21/C21-1,E21/D21-1) -> 0.17067726 | D38: Average YoY growth, FY2024-FY2026
B39: Basic/Diluted Shares growth | C39: =AVERAGE(D25/C25-1,E25/D25-1) -> 0.01193042 | D39: Average YoY growth, FY2024-FY2026

Sheet SBI BS Forecasting
B1: State Bank Of India
B3: Balance Sheet Forecast (2024-2029)
B4: INR ( Rupees in Crores)
B5: Line Items | C5: 2024 | D5: 2025 | E5: 2026 | F5: 2027 | G5: 2028 | H5: 2029
B7: Capital and Liabilities
B8: Capital | C8: 892.4612 | D8: 892.462 | E8: 923.0618 | F8: =E8*(1+$C$31) -> 938.8867 | G8: =F8*(1+$C$31) -> 954.9829 | H8: =G8*(1+$C$31) -> 971.35506
B9: Reserves & Surplus | C9: 414046.71 | D9: 486144.3 | E9: 595207.81 | F9: =E9+'SBI IS Forecasting'!F22+'[1]SBI CF Forecasting'!F24+$C$39 -> 701407.34 | G9: =F9+'[1]SBI IS Forecasting'!G22+'[1]SBI CF Forecasting'!G24+$C$39 -> 820022.59 | H9: =G9+'[1]SBI IS Forecasting'!H22+'[1]SBI CF Forecasting'!H24+$C$39 -> 952546.71
B10: Minority Interest & Other Equity | C10: 15617.962 | D10: 18025.839 | E10: 18768.282 | F10: =E10*(1+$C$32) -> 20601.58 | G10: =F10*(1+$C$32) -> 22613.955 | H10: =G10*(1+$C$32) -> 24822.901
B12: Deposits | C12: 4966537.5 | D12: 5439898 | E12: 6043097.1 | F12: =E12*(1+$C$33) -> 6666123 | G12: =F12*(1+$C$33) -> 7353381.1 | H12: =G12*(1+$C$33) -> 8111493.5
B13: Borrowings | C13: 639609.5 | D13: 610857.24 | E13: 777302.15 | F13: =E13*(1+$C$34) -> 865729.88 | G13: =F13*(1+$C$34) -> 964217.36 | H13: =G13*(1+$C$34) -> 1073909
B14: Other Liabilities and Provisions | C14: 697074.68 | D14: 758367.48 | E14: 886270.15 | F14: =F24-(F8+F9+F10+F12+F13) -> 1023877.4 | G14: =G24-(G8+G9+G10+G12+G13) -> 1199662.2 | H14: =H24-(H8+H9+H10+H12+H13) -> 1421430.9
B15: Total Capital and Liabilities | C15: =SUM(C8:C14) -> 6733778.8 | D15: =SUM(D8:D14) -> 7314185.3 | E15: =SUM(E8:E14) -> 8321568.6 | F15: =SUM(F8:F14) -> 9278678.1 | G15: =SUM(G8:G14) -> 10360852 | H15: =SUM(H8:H14) -> 11585174
B17: Assets
B18: Cash and Balances with Reserve Bank of India | C18: 225356.34 | D18: 227485.16 | E18: 268681.74 | F18: ='[1]SBI CF Forecasting'!F32-F19 -> 300265.95 | G18: ='[1]SBI CF Forecasting'!G32-G19 -> 336142.02 | H18: ='[1]SBI CF Forecasting'!H32-H19 -> 376553.9
B19: Balances with Banks and Money at Call & Short Notice | C19: 101215.97 | D19: 130447.79 | E19: 133161.47 | F19: =E19*(1+$C$35) -> 153775.48 | G19: =F19*(1+$C$35) -> 177580.64 | H19: =G19*(1+$C$35) -> 205070.95
B20: Investments | C20: 2110548.2 | D20: 2205601.1 | E20: 2359502.2 | F20: =E20*(1+$C$36) -> 2494954.6 | G20: =F20*(1+$C$36) -> 2638183 | H20: =G20*(1+$C$36) -> 2789633.8
B21: Advances | C21: 3784272.7 | D21: 4250830.7 | E21: 4978013.2 | F21: =E21*(1+$C$37) -> 5710669.8 | G21: =F21*(1+$C$37) -> 6551157.7 | H21: =G21*(1+$C$37) -> 7515347.3
B22: Fixed Assets | C22: 44708.177 | D22: 46337.695 | E22: 57152.101 | F22: =E22-'[1]SBI CF Forecasting'!F19-'[1]SBI CF Forecasting'!F9 -> 60486.433 | G22: =F22-'[1]SBI CF Forecasting'!G19-'[1]SBI CF Forecasting'!G9 -> 63661.756 | H22: =G22-'[1]SBI CF Forecasting'!H19-'[1]SBI CF Forecasting'!H9 -> 66570.943
B23: Other Assets | C23: 467677.42 | D23: 453482.86 | E23: 525057.89 | F23: =E23*(1+$C$38) -> 558525.82 | G23: =F23*(1+$C$38) -> 594127.05 | H23: =G23*(1+$C$38) -> 631997.56
B24: Total Assets | C24: =SUM(C17:C23) -> 6733778.8 | D24: =SUM(D17:D23) -> 7314185.3 | E24: =SUM(E17:E23) -> 8321568.6 | F24: =SUM(F17:F23) -> 9278678.1 | G24: =SUM(G17:G23) -> 10360852 | H24: =SUM(H17:H23) -> 11585174
B26: Balance Check (Total Assets − Total Capital & Liabilities) | C26: =C24-C15 -> 0 | D26: =D24-D15 -> 9.9998899e-05 | E26: =E24-E15 -> 0 | F26: =F24-F15 -> 0 | G26: =G24-G15 -> 0 | H26: =H24-H15 -> 0
B29: Key Forecast Assumptions (applied 2027-2029)
B30: Driver / Assumption | C30: Value | D30: Basis / Note
B31: Capital growth | C31: =AVERAGE(D8/C8-1,E8/D8-1) -> 0.017143923 | D31: Formula: avg YoY growth, FY2024-FY2026 (row 8)
B32: Minority Interest & Other Equity growth | C32: =AVERAGE(D10/C10-1,E10/D10-1) -> 0.097680633 | D32: Formula: avg YoY growth, FY2024-FY2026 (row 10)
B33: Deposits growth | C33: =AVERAGE(D12/C12-1,E12/D12-1) -> 0.10309712 | D33: Formula: avg YoY growth, FY2024-FY2026 (row 12)
B34: Borrowings growth | C34: =AVERAGE(D13/C13-1,E13/D13-1) -> 0.11376237 | D34: Formula: avg YoY growth, FY2024-FY2026 (row 13)
B35: Balances with Banks & Money at Call growth | C35: =AVERAGE(D19/C19-1,E19/D19-1) -> 0.15480463 | D35: Formula: avg YoY growth, FY2024-FY2026 (row 19)
B36: Investments growth | C36: =AVERAGE(D20/C20-1,E20/D20-1) -> 0.057407218 | D36: Formula: avg YoY growth, FY2024-FY2026 (row 20)
B37: Advances growth | C37: =AVERAGE(D21/C21-1,E21/D21-1) -> 0.14717851 | D37: Formula: avg YoY growth, FY2024-FY2026 (row 21)
B38: Other Assets growth | C38: =AVERAGE(D23/C23-1,E23/D23-1) -> 0.063741422 | D38: Formula: avg YoY growth, FY2024-FY2026 (row 23)
B39: Other Reserve Movements (Rs Cr, flat p.a.) | C39: =AVERAGE((D9-C9)-('SBI IS Forecasting'!D22+'SBI CF Forecasting'!D24),(E9-D9)-('SBI IS Forecasting'!E22+'SBI CF Forecasting'!E24)) -> 23358.92 | D39: Formula: AVERAGE of (actual reserve change less Net Profit less Dividends) for FY2025 and FY2026 - captures OCI/associate equity pickup etc. not modeled elsewhere
B40: Other Liabilities and Provisions | C40: Plug | D40: Balancing item = Total Assets less all other liabilities & equity, so the Balance Sheet ties out exactly each forecast year

Sheet SBI CF Forecasting
B1: State Bank Of India
B3: Cash Flow Forecast (2024-2029)
B4: INR ( Rupees in Crores)
B5: Line Items | C5: 2024 | D5: 2025 | E5: 2026 | F5: 2027 | G5: 2028 | H5: 2029
B7: Cash Flow From Operating Activites
B8: Net Profit/(Loss) before taxes (including share in profit from associates and net of minority interest) | C8: ='[1]SBI IS Forecasting'!C17+'[1]SBI IS Forecasting'!C20-'[1]SBI IS Forecasting'!C21 -> 90186.443 | D8: ='[1]SBI IS Forecasting'!D17+'[1]SBI IS Forecasting'!D20-'[1]SBI IS Forecasting'!D21 -> 104909.48 | E8: ='[1]SBI IS Forecasting'!E17+'[1]SBI IS Forecasting'!E20-'[1]SBI IS Forecasting'!E21 -> 112158.3 | F8: ='SBI IS Forecasting'!F17+'SBI IS Forecasting'!F20-'SBI IS Forecasting'!F21 -> 133010.53 | G8: ='SBI IS Forecasting'!G17+'SBI IS Forecasting'!G20-'SBI IS Forecasting'!G21 -> 153035.15 | H8: ='SBI IS Forecasting'!H17+'SBI IS Forecasting'!H20-'SBI IS Forecasting'!H21 -> 175481.11
B9: Depreciation on Fixed Assets | C9: 3849.1245 | D9: 3991.4767 | E9: 4829.7185 | F9: =E9*(1+$C$37) -> 5426.1669 | G9: =F9*(1+$C$37) -> 6096.2739 | H9: =G9*(1+$C$37) -> 6849.1362
B10: Other Operating Activities | C10: 11088.191 | D10: 20360.15 | E10: 28893.687 | F10: =$C$38*'SBI IS Forecasting'!F11 -> 23404.011 | G10: =$C$38*'SBI IS Forecasting'!G11 -> 25529.635 | H10: =$C$38*'SBI IS Forecasting'!H11 -> 27864.1
B11: Tax refund / (Taxes paid) | C11: -31268.268 | D11: -33761.445 | E11: -36322.966 | F11: =E11*(1+$C$39) -> -39149.006 | G11: =F11*(1+$C$39) -> -42194.921 | H11: =G11*(1+$C$39) -> -45477.818
B12: Change in Net Working Capital | C12: -52223.064 | D12: -50015.65 | E12: -71461.347 | F12: =$C$40*'SBI BS Forecasting'!F21 -> -75992.854 | G12: =$C$40*'SBI BS Forecasting'!G21 -> -87177.369 | H12: =$C$40*'SBI BS Forecasting'!H21 -> -100008
B14: Total Cash Flow From Operating Activites | C14: =C8+C9+C1+C10+C11+C12 -> 21632.427 | D14: =D8+D9+D1+D10+D11+D12 -> 45484.008 | E14: =E8+E9+E1+E10+E11+E12 -> 38097.388 | F14: =SUM(F8:F12) -> 46698.85 | G14: =SUM(G8:G12) -> 55288.769 | H14: =SUM(H8:H12) -> 64708.523
B16: Cash Flow From Investing Activites
B17: Purchase of Investments | C17: -82.161 | D17: - | E17: -108.2683 | F17: =E17*(1+$C$41) -> -114.48368 | G17: =F17*(1+$C$41) -> -121.05587 | H17: =G17*(1+$C$41) -> -128.00535
B18: Sale Of Investments | C18: - | D18: -6.519 | E18: 7779.4109 | F18: =E18*(1+$C$41) -> 8226.0052 | G18: =F18*(1+$C$41) -> 8698.2373 | H18: =G18*(1+$C$41) -> 9197.5789
B19: Purchase of Fixed Assets | C19: -4175.1262 | D19: -5637.2241 | E19: -8362.9582 | F19: =-$C$42*'SBI BS Forecasting'!E22 -> -8760.4981 | G19: =-$C$42*'SBI BS Forecasting'!F22 -> -9271.5975 | H19: =-$C$42*'SBI BS Forecasting'!G22 -> -9758.3235
B20: Income from Investments in Associates | C20: 5.5719 | D20: 9.0009 | E20: 0.9299 | F20: =$C$43 -> 0.9299 | G20: =$C$43 -> 0.9299 | H20: =$C$43 -> 0.9299
B21: Total Cash Flow From Investing Activites | C21: =SUM(C17:C20) -> -4251.7153 | D21: =SUM(D17:D20) -> -5634.7422 | E21: =SUM(E17:E20) -> -690.8857 | F21: =SUM(F17:F20) -> -648.04664 | G21: =SUM(G17:G20) -> -693.48611 | H21: =SUM(H17:H20) -> -687.82002
B23: Cash Flow From Financing Activites
B24: Dividend paid | C24: -10084.811 | D24: -12226.718 | E24: -14190.146 | F24: =-$C$44*'SBI IS Forecasting'!F22 -> -15713.514 | G24: =-$C$44*'SBI IS Forecasting'!G22 -> -18068.572 | H24: =-$C$44*'SBI IS Forecasting'!H22 -> -20706.859
B25: Other Financing Activities | C25: 188.53 | D25: 1489.9243 | E25: 10763.008 | F25: =E25*(1+$C$45) -> 11930.039 | G25: =F25*(1+$C$45) -> 13223.61 | H25: =G25*(1+$C$45) -> 14657.442
B26: Total Cash Flow From Financing Activites | C26: =SUM(C24:C25) -> -9896.2815 | D26: =SUM(D24:D25) -> -10736.794 | E26: =SUM(E24:E25) -> -3427.1374 | F26: =SUM(F24:F25) -> -3783.4757 | G26: =SUM(G24:G25) -> -4844.9624 | H26: =SUM(H24:H25) -> -6049.4169
B28: Effect of fluctuation in foreign currency translation reserve | C28: 775.9581 | D28: 2248.1669 | E28: 9930.8997 | F28: =$C$46 -> 9930.8997 | G28: =$C$46 -> 9930.8997 | H28: =$C$46 -> 9930.8997
B29: Net Change in Cash | C29: =C14+C21+C26+C28 -> 8260.3878 | D29: =D14+D21+D26+D28 -> 31360.639 | E29: =E14+E21+E26+E28 -> 43910.265 | F29: =F14+F21+F26+F28 -> 52198.228 | G29: =G14+G21+G26+G28 -> 59681.221 | H29: =H14+H21+H26+H28 -> 67902.186
B31: Cash and cash equivalents at the beginning of the year | C31: 318311.91 | D31: ='[1]SBI BS Forecasting'!C18+'[1]SBI BS Forecasting'!C19 -> 326572.3 | E31: ='[1]SBI BS Forecasting'!D18+'[1]SBI BS Forecasting'!D19 -> 357932.94 | F31: ='SBI BS Forecasting'!E18+'SBI BS Forecasting'!E19 -> 401843.21 | G31: ='SBI BS Forecasting'!F18+'SBI BS Forecasting'!F19 -> 454041.44 | H31: ='SBI BS Forecasting'!G18+'SBI BS Forecasting'!G19 -> 513722.66
B32: Cash and cash equivalents at the end of the year | C32: =C29+C31 -> 326572.3 | D32: =D31+D29 -> 357932.94 | E32: =E31+E29 -> 401843.21 | F32: =F31+F29 -> 454041.44 | G32: =G31+G29 -> 513722.66 | H32: =H31+H29 -> 581624.84
B35: Key Forecast Assumptions (applied 2027-2029)
B36: Driver / Assumption | C36: Value | D36: Basis / Note
B37: Depreciation growth | C37: =AVERAGE(D9/C9-1,E9/D9-1) -> 0.12349547 | D37: Formula: avg YoY growth, FY2024-FY2026 (row 9)
B38: Other Operating Activities (% of Net Revenue) | C38: =AVERAGE(C10/'SBI IS Forecasting'!C11,D10/'SBI IS Forecasting'!D11,E10/'SBI IS Forecasting'!E11) -> 0.053986535 | D38: Formula: AVERAGE of ratio to 'SBI IS Forecasting' Net Revenue (row 11) each year, FY2024-FY2026
B39: Tax paid growth | C39: =AVERAGE(D11/C11-1,E11/D11-1) -> 0.077803122 | D39: Formula: avg YoY growth, FY2024-FY2026 (row 11)
B40: Change in NWC (% of Advances) | C40: =AVERAGE(C12/'SBI BS Forecasting'!C21,D12/'SBI BS Forecasting'!D21,E12/'SBI BS Forecasting'!E21) -> -0.01330717 | D40: Formula: AVERAGE of ratio to 'SBI BS Forecasting' Advances (row 21) each year, FY2024-FY2026
B41: Purchase/Sale of Investments growth | C41: ='SBI BS Forecasting'!$C$36 -> 0.057407218 | D41: Formula: linked directly to 'SBI BS Forecasting' Investments growth assumption for consistency
B42: Capex (% of prior-year Fixed Assets) | C42: =AVERAGE(-D19/'SBI BS Forecasting'!C22,-E19/'SBI BS Forecasting'!D22) -> 0.15328392 | D42: Formula: AVERAGE of (Purchase of FA / prior-year Fixed Assets) for FY2025 and FY2026
B43: Income from Investments in Associates (Rs Cr, flat p.a.) | C43: =E20 -> 0.9299 | D43: Formula: =E20, i.e. held flat at FY2026 actual (small, historically too volatile to extrapolate)
B44: Dividend payout ratio (% of Net Profit) | C44: =AVERAGE(-C24/'SBI IS Forecasting'!C22,-D24/'SBI IS Forecasting'!D22,-E24/'SBI IS Forecasting'!E22) -> 0.15944044 | D44: Formula: AVERAGE of (-Dividend paid / Net Profit) each year, referencing 'SBI IS Forecasting'
B45: Other Financing Activities growth | C45: =AVERAGE('SBI BS Forecasting'!$C$33,'SBI BS Forecasting'!$C$34) -> 0.10842974 | D45: Formula: AVERAGE of 'SBI BS Forecasting' Deposits growth and Borrowings growth assumptions (normalizes an otherwise extreme, small-base historical growth rate)
B46: FX Translation Effect (Rs Cr, flat p.a.) | C46: =E28 -> 9930.8997 | D46: Formula: =E28, i.e. held flat at FY2026 actual (inherently unpredictable currency effect)

Sheet HDFC IS
B1: HDFC Bank Limited
B3: Income Statement (2024-2026)
B4: INR ( Rupees in Crores)
B5: Line Items | C5: 2024 | D5: 2025 | E5: 2026
B7: Interest Earned | C7: 283649.02 | D7: 336367.43 | E7: 348615.15
B8: Interest Expense | C8: 154138.55 | D8: 183894.2 | E8: 185491.23
B9: Net Interest Income | C9: =C7-C8 -> 129510.47 | D9: =D7-D8 -> 152473.23 | E9: =E7-E8 -> 163123.92
B10: Other Income | C10: 124345.75 | D10: 134548.5 | E10: 146847.66
B11: Net Revenue | C11: =C9+C10 -> 253856.22 | D11: =D9+D10 -> 287021.73 | E11: =E9+E10 -> 309971.58
B13: Operating expenses | C13: 152269.34 | D13: 176605.07 | E13: 181173.91
B14: Operating Income | C14: =C11-C13 -> 101586.88 | D14: =D11-D13 -> 110416.66 | E14: =E11-E13 -> 128797.67
B16: Provisions and contingencies (ex-tax) | C16: 26057.36 | D16: 15845.79 | E16: 29080.81
B17: Net Profit Before Taxation | C17: =C14-C16 -> 75529.52 | D17: =D14-D16 -> 94570.87 | E17: =E14-E16 -> 99716.86
B18: Taxation | C18: 10083.02 | D18: 21130.7 | E18: 20497.4
B19: Net Profit After taxation | C19: =C17-C18 -> 65446.5 | D19: =D17-D18 -> 73440.17 | E19: =E17-E18 -> 79219.46
B20: Less: Minority Interest | C20: 1384.46 | D20: 2647.92 | E20: 3193.49
B21: Net Profit | C21: =C19-C20 -> 64062.04 | D21: =D19-D20 -> 70792.25 | E21: =E19-E20 -> 76025.97
B23: Basic EPS | C23: =(C21)/C24 -> 45.21 | D23: =(D21)/D24 -> 46.404149 | E23: =(E21)/E24 -> 49.504253
B24: Basic Shares | C24: 1416.9883 | D24: 1525.5586 | E24: 1535.7462
B25: Diluted EPS | C25: =(C21)/C26 -> 45.005 | D25: =(D21)/D26 -> 46.197156 | E25: =(E21)/E26 -> 49.278068
B26: Diluted Shares | C26: 1423.4427 | D26: 1532.3941 | E26: 1542.7953

Sheet HDFC BS
B1: HDFC Bank Limited
B3: Balance Sheet (2024-2026)
B4: INR ( Rupees in Crores)
B5: Line Items | C5: 2024 | D5: 2025 | E5: 2026
B7: Capital and Liabilities
B8: Capital | C8: 759.69 | D8: 765.22 | E8: 1539.34
B9: Reserves & Surplus | C9: 452982.84 | D9: 517218.98 | E9: 579975.02
B10: Minority Interest & Other Equity | C10: 16036.12 | D10: 20164.23 | E10: 26930.07
B12: Deposits | C12: 2376887.3 | D12: 2710898.2 | E12: 3099638.3
B13: Borrowings | C13: 730615.46 | D13: 634605.57 | E13: 588484.55
B14: Other Liabilities and Provisions | C14: 452912.87 | D14: 508765.19 | E14: 611473.57
B15: Total Capital and Liabilities | C15: =SUM(C8:C14) -> 4030194.3 | D15: =SUM(D8:D14) -> 4392417.4 | E15: =SUM(E8:E14) -> 4908040.8
B17: Assets
B18: Cash and Balances with Reserve Bank of India | C18: 178718.67 | D18: 144390.25 | E18: 200707.11
B19: Balances with Banks and Money at Call & Short Notice | C19: 50115.84 | D19: 105557.65 | E19: 111218.94
B20: Investments | C20: 1005681.6 | D20: 1186472.9 | E20: 1280216.3
B21: Advances | C21: 2571916.6 | D21: 2724938.2 | E21: 3050783.2
B22: Fixed Assets | C22: 12603.76 | D22: 15257.94 | E22: 16491.59
B23: Other Assets | C23: 211157.71 | D23: 215800.53 | E23: 248623.68
B24: Total Assets | C24: =SUM(C17:C23) -> 4030194.3 | D24: =SUM(D17:D23) -> 4392417.4 | E24: =SUM(E17:E23) -> 4908040.8
B26: CET 1 Capital | C26: 402231.82 | D26: 458210.41 | E26: 514070.42
B27: Tier 1 Capital | C27: 414281.32 | D27: 470466.91 | E27: 527282.92
B28: Tier 2 Capital | C28: 49721.5 | D28: 49575.61 | E28: 58933.47
B29: Total Capital (Tier1 + Tier 2) | C29: =C27+C28 -> 464002.82 | D29: =D27+D28 -> 520042.52 | E29: =E27+E28 -> 586216.39
B30: Risk-Weighted Assets | C30: 2468028.1 | D30: 2660003.9 | E30: 2974116.6
B32: Total Employees | C32: 213527 | D32: 214521 | E32: 211178

Sheet HDFC CF
B1: HDFC Bank Limited
B3: Cash Flow (2024-2026)
B4: INR ( Rupees in Crores)
B5: Line Items | C5: 2024 | D5: 2025 | E5: 2026
B7: Cash Flow From Operating Activites
B8: Net Profit/(Loss) before taxes (including share in profit from associates and net of minority interest) | C8: ='HDFC IS'!C21+'HDFC IS'!C18+'HDFC IS'!C20-345.38 -> 75184.14 | D8: ='HDFC IS'!D21+'HDFC IS'!D18+'HDFC IS'!D20-976.74 -> 93594.13 | E8: ='HDFC IS'!E21+'HDFC IS'!E18+'HDFC IS'!E20-768.9 -> 98947.96
B9: Depreciation on Fixed Assets | C9: 3092.08 | D9: 3805.23 | E9: 4194.9
B10: Other Operating Activities | C10: 13342.18 | D10: 20242.8 | E10: 30402.47
B11: Tax refund / (Taxes paid) | C11: -22842.84 | D11: 29308.36 | E11: -22656.37
B12: Change in Net Working Capital | C12: -49706.22 | D12: -19708.68 | E12: 2617.42
B14: Total Cash Flow From Operating Activites | C14: =C8+C9+C1+C10+C11+C12 -> 19069.34 | D14: =D8+D9+D1+D10+D11+D12 -> 127241.84 | E14: =E8+E9+E1+E10+E11+E12 -> 113506.38
B16: Cash Flow From Investing Activites
B17: Purchase of Investments | C17: - | D17: - | E17: -
B18: Sale Of Investments | C18: 9500.67 | D18: 192 | E18: 9806
B19: Purchase and Sale of Fixed Assets | C19: -4186.9 | D19: -3975.17 | E19: -3362.41
B20: Income from Investments in Associates | C20: - | D20: -67.47 | E20: -80.87
B21: Total Cash Flow From Investing Activites | C21: =SUM(C17:C20) -> 5313.77 | D21: =SUM(D17:D20) -> -3850.64 | E21: =SUM(E17:E20) -> 6362.72
B23: Cash Flow From Financing Activites
B24: Dividend paid | C24: -8404.42 | D24: -14826.19 | E24: -20705.98
B25: Other Financing Activities | C25: 4421.36 | D25: -87651.35 | E25: -38298.87
B26: Total Cash Flow From Financing Activites | C26: =SUM(C24:C25) -> -3983.06 | D26: =SUM(D24:D25) -> -102477.54 | E26: =SUM(E24:E25) -> -59004.85
B28: Effect of fluctuation in foreign currency translation reserve | C28: 104.94 | D28: 199.73 | E28: 1113.9
B29: Net Change in Cash | C29: =C14+C21+C26+C28 -> 20504.99 | D29: =D14+D21+D26+D28 -> 21113.39 | E29: =E14+E21+E26+E28 -> 61978.15
B31: Cash and cash equivalents at the beginning of the year | C31: 208329.52 | D31: ='HDFC BS'!C18+'HDFC BS'!C19 -> 228834.51 | E31: ='HDFC BS'!D18+'HDFC BS'!D19 -> 249947.9
B32: Cash and cash equivalents at the end of the year | C32: =C29+C31 -> 228834.51 | D32: =D31+D29 -> 249947.9 | E32: =E31+E29 -> 311926.05

Sheet Ratio Analysis
B1: State Bank Of India | G1: VS | I1: HDFC Bank Limited
B3: Income Statement Growth Horizontal | I3: Income Statement Growth Horizontal
B4: INR ( Rupees in Crores) | I4: INR ( Rupees in Crores)
B5: Category | C5: Ratios | D5: 2024 | E5: 2025 | F5: 2026 | I5: Category | J5: Ratios | K5: 2024 | L5: 2025 | M5: 2026 | N5: Comments
B6: Profitability | C6: ROA | D6: ='SBI IS'!C22/'SBI BS'!C24 -> 0.0099624096 | E6: ='SBI IS'!D22/'SBI BS'!D24 -> 0.010604234 | F6: ='SBI IS'!E22/'SBI BS'!E24 -> 0.010009986 | I6: Profitability | J6: ROA | K6: ='HDFC IS'!C21/'HDFC BS'!C24 -> 0.015895522 | L6: ='HDFC IS'!D21/'HDFC BS'!D24 -> 0.016116922 | M6: ='HDFC IS'!E21/'HDFC BS'!E24 -> 0.015490085 | N6: HDFC generates a meaningfully higher Return on Assets than SBI across all three years, reflecting a more profitable, fee/retail-heavy asset base versus SBI's larger, lower-yielding balance sheet.
B7: Profitability | C7: ROE | D7: ='SBI IS'!C22/('SBI BS'!C8+'SBI BS'!C9+'SBI BS'!C10) -> 0.15580897 | E7: ='SBI IS'!D22/('SBI BS'!D8+'SBI BS'!D9+'SBI BS'!D10) -> 0.15356777 | F7: ='SBI IS'!E22/('SBI BS'!E8+'SBI BS'!E9+'SBI BS'!E10) -> 0.13546739 | I7: Profitability | J7: ROE | K7: ='HDFC IS'!C21/('HDFC BS'!C8+'HDFC BS'!C9+'HDFC BS'!C10) -> 0.13636644 | L7: ='HDFC IS'!D21/('HDFC BS'!D8+'HDFC BS'!D9+'HDFC BS'!D10) -> 0.13154781 | M7: ='HDFC IS'!E21/('HDFC BS'!E8+'HDFC BS'!E9+'HDFC BS'!E10) -> 0.12495138 | N7: SBI's Return on Equity is higher than HDFC's, mainly because SBI runs on a much thinner equity base relative to assets (higher leverage), which lifts ROE even though its ROA is lower.
B8: Profitability | C8: NIM | D8: ='SBI IS'!C9/('SBI BS'!C21+'SBI BS'!C20) -> 0.030442395 | E8: ='SBI IS'!D9/('SBI BS'!D21+'SBI BS'!D20) -> 0.029330343 | F8: ='SBI IS'!E9/('SBI BS'!E21+'SBI BS'!E20) -> 0.027247341 | I8: Profitability | J8: NIM | K8: ='HDFC IS'!C9/('HDFC BS'!C21+'HDFC BS'!C20) -> 0.036200395 | L8: ='HDFC IS'!D9/('HDFC BS'!D21+'HDFC BS'!D20) -> 0.038981643 | M8: ='HDFC IS'!E9/('HDFC BS'!E21+'HDFC BS'!E20) -> 0.037664266 | N8: HDFC's Net Interest Margin is consistently wider than SBI's, indicating HDFC earns more spread on its advances and investments; SBI's NIM has also been gradually compressing over the period.
B9: Profitability | C9: Net Profit Margin | D9: ='SBI IS'!C22/'SBI IS'!C11 -> 0.2003491 | E9: ='SBI IS'!D22/'SBI IS'!D11 -> 0.21402136 | F9: ='SBI IS'!E22/'SBI IS'!E11 -> 0.20948359 | I9: Profitability | J9: Net Profit Margin | K9: ='HDFC IS'!C21/'HDFC IS'!C11 -> 0.25235561 | L9: ='HDFC IS'!D21/'HDFC IS'!D11 -> 0.24664422 | M9: ='HDFC IS'!E21/'HDFC IS'!E11 -> 0.24526755 | N9: HDFC converts a larger share of Net Revenue into Net Profit than SBI in every year, consistent with HDFC's better cost efficiency and asset quality.
B10: Profitability | C10: Cost-to-Income Ratio | D10: ='SBI IS'!C13/'SBI IS'!C11 -> 0.7044996 | E10: ='SBI IS'!D13/'SBI IS'!D11 -> 0.65279672 | F10: ='SBI IS'!E13/'SBI IS'!E11 -> 0.66052533 | I10: Profitability | J10: Cost-to-Income Ratio | K10: ='HDFC IS'!C13/'HDFC IS'!C11 -> 0.59982513 | L10: ='HDFC IS'!D13/'HDFC IS'!D11 -> 0.61530209 | M10: ='HDFC IS'!E13/'HDFC IS'!E11 -> 0.58448555 | N10: HDFC's Cost-to-Income Ratio is lower than SBI's, showing HDFC keeps a smaller share of revenue tied up in operating expenses; SBI has improved this ratio since FY2024 but still lags HDFC.
B11: Profitability | C11: PPOP Margin | D11: ='SBI IS'!C14/'SBI IS'!C11 -> 0.2955004 | E11: ='SBI IS'!D14/'SBI IS'!D11 -> 0.34720328 | F11: ='SBI IS'!E14/'SBI IS'!E11 -> 0.33947467 | I11: Profitability | J11: PPOP Margin | K11: ='HDFC IS'!C14/'HDFC IS'!C11 -> 0.40017487 | L11: ='HDFC IS'!D14/'HDFC IS'!D11 -> 0.38469791 | M11: ='HDFC IS'!E14/'HDFC IS'!E11 -> 0.41551445 | N11: HDFC's Pre-Provision Operating Profit Margin is higher than SBI's in most years, mirroring its lower cost-to-income ratio and stronger core operating profitability.
B12: Profitability | C12: Operating Expense Ratio | D12: ='SBI IS'!C13/'SBI BS'!C24 -> 0.035031421 | E12: ='SBI IS'!D13/'SBI BS'!D24 -> 0.03234448 | F12: ='SBI IS'!E13/'SBI BS'!E24 -> 0.031562613 | I12: Profitability | J12: Operating Expense Ratio | K12: ='HDFC IS'!C13/'HDFC BS'!C24 -> 0.037782134 | L12: ='HDFC IS'!D13/'HDFC BS'!D24 -> 0.040206805 | M12: ='HDFC IS'!E13/'HDFC BS'!E24 -> 0.036913692 | N12: Both banks keep Operating Expenses at a similar, low percentage of Total Assets, with SBI slightly more efficient on this basis in FY2026 despite its larger, lower-margin balance sheet.
B13: Liquidity | C13: Loan-to-Deposit Ratio | D13: ='SBI BS'!C21/'SBI BS'!C12 -> 0.76195391 | E13: ='SBI BS'!D21/'SBI BS'!D12 -> 0.78141736 | F13: ='SBI BS'!E21/'SBI BS'!E12 -> 0.82375198 | I13: Liquidity | J13: Loan-to-Deposit Ratio | K13: ='HDFC BS'!C21/'HDFC BS'!C12 -> 1.0820524 | L13: ='HDFC BS'!D21/'HDFC BS'!D12 -> 1.0051791 | M13: ='HDFC BS'!E21/'HDFC BS'!E12 -> 0.98423846 | N13: HDFC's Loan-to-Deposit Ratio is well above 100% in FY2024 and stays near parity thereafter, showing it lends out close to (or more than) its deposit base; SBI runs a more conservative, sub-85% ratio with room to grow advances.
B14: Liquidity | C14: Liquid Assets / Total Assets | D14: =('SBI BS'!C18+'SBI BS'!C19+'SBI BS'!C20)/'SBI BS'!C24 -> 0.36192465 | E14: =('SBI BS'!D18+'SBI BS'!D19+'SBI BS'!D20)/'SBI BS'!D24 -> 0.35048798 | F14: =('SBI BS'!E18+'SBI BS'!E19+'SBI BS'!E20)/'SBI BS'!E24 -> 0.33182991 | I14: Liquidity | J14: Liquid Assets / Total Assets | K14: =('HDFC BS'!C18+'HDFC BS'!C19+'HDFC BS'!C20)/'HDFC BS'!C24 -> 0.30631678 | L14: =('HDFC BS'!D18+'HDFC BS'!D19+'HDFC BS'!D20)/'HDFC BS'!D24 -> 0.32702283 | M14: =('HDFC BS'!E18+'HDFC BS'!E19+'HDFC BS'!E20)/'HDFC BS'!E24 -> 0.32439468 | N14: SBI holds a larger share of Total Assets in liquid form (cash, interbank balances and investments) than HDFC, consistent with its more conservative balance sheet mix.
B15: Liquidity | C15: Liquid Assets / Deposits | D15: =('SBI BS'!C18+'SBI BS'!C19+'SBI BS'!C20)/'SBI BS'!C12 -> 0.49070817 | E15: =('SBI BS'!D18+'SBI BS'!D19+'SBI BS'!D20)/'SBI BS'!D12 -> 0.47124671 | F15: =('SBI BS'!E18+'SBI BS'!E19+'SBI BS'!E20)/'SBI BS'!E12 -> 0.45694208 | I15: Liquidity | J15: Liquid Assets / Deposits | K15: =('HDFC BS'!C18+'HDFC BS'!C19+'HDFC BS'!C20)/'HDFC BS'!C12 -> 0.51938354 | L15: =('HDFC BS'!D18+'HDFC BS'!D19+'HDFC BS'!D20)/'HDFC BS'!D12 -> 0.52986895 | M15: =('HDFC BS'!E18+'HDFC BS'!E19+'HDFC BS'!E20)/'HDFC BS'!E12 -> 0.51365424 | N15: HDFC holds slightly more liquid assets relative to its deposit base than SBI, even though HDFC's loan book is proportionally larger, pointing to a well-buffered liquidity position.
B16: Liquidity | C16: Cash & RBI / Deposits | D16: ='SBI BS'!C18/'SBI BS'!C12 -> 0.045374939 | E16: ='SBI BS'!D18/'SBI BS'!D12 -> 0.041817908 | F16: ='SBI BS'!E18/'SBI BS'!E12 -> 0.044460933 | I16: Liquidity | J16: Cash & RBI / Deposits | K16: ='HDFC BS'!C18/'HDFC BS'!C12 -> 0.075190217 | L16: ='HDFC BS'!D18/'HDFC BS'!D12 -> 0.053262881 | M16: ='HDFC BS'!E18/'HDFC BS'!E12 -> 0.064751784 | N16: HDFC keeps a higher proportion of Cash & RBI balances against deposits than SBI in every year, though both banks show some year-to-year fluctuation in this cushion.
B17: Liquidity | C17: Cash & RBI / Total Assets | D17: ='SBI BS'!C18/'SBI BS'!C24 -> 0.033466549 | E17: ='SBI BS'!D18/'SBI BS'!D24 -> 0.031101913 | F17: ='SBI BS'!E18/'SBI BS'!E24 -> 0.032287391 | I17: Liquidity | J17: Cash & RBI / Total Assets | K17: ='HDFC BS'!C18/'HDFC BS'!C24 -> 0.044344927 | L17: ='HDFC BS'!D18/'HDFC BS'!D24 -> 0.032872616 | M17: ='HDFC BS'!E18/'HDFC BS'!E24 -> 0.040893529 | N17: Cash & RBI balances make up a slightly larger share of Total Assets for HDFC than for SBI, though both ratios are relatively stable and modest in size.
B18: Growth Ratios | C18: Loan Growth | D18: - | E18: =('SBI BS'!D21-'SBI BS'!C21)/'SBI BS'!C21 -> 0.1232887 | F18: =('SBI BS'!E21-'SBI BS'!D21)/'SBI BS'!D21 -> 0.17106832 | I18: Growth Ratios | J18: Loan Growth | K18: - | L18: =('HDFC BS'!D21-'HDFC BS'!C21)/'HDFC BS'!C21 -> 0.059497072 | M18: =('HDFC BS'!E21-'HDFC BS'!D21)/'HDFC BS'!D21 -> 0.11957889 | N18: HDFC's loan book grew more slowly than SBI's in FY2025 but closed the gap in FY2026; SBI has shown consistently strong double-digit advances growth across both years.
B19: Growth Ratios | C19: Deposit Growth | D19: - | E19: =('SBI BS'!D12-'SBI BS'!C12)/'SBI BS'!C12 -> 0.095309969 | F19: =('SBI BS'!E12-'SBI BS'!D12)/'SBI BS'!D12 -> 0.11088427 | I19: Growth Ratios | J19: Deposit Growth | K19: - | L19: =('HDFC BS'!D12-'HDFC BS'!C12)/'HDFC BS'!C12 -> 0.14052452 | M19: =('HDFC BS'!E12-'HDFC BS'!D12)/'HDFC BS'!D12 -> 0.14339899 | N19: HDFC has grown deposits faster than SBI in both years, which helps explain why HDFC's Loan-to-Deposit ratio has been able to ease down from FY2024 while still funding strong loan growth.
B20: Growth Ratios | C20: NII Growth | D20: - | E20: =('SBI IS'!D9-'SBI IS'!C9)/'SBI IS'!C9 -> 0.055261985 | F20: =('SBI IS'!E9-'SBI IS'!D9)/'SBI IS'!D9 -> 0.055755684 | I20: Growth Ratios | J20: NII Growth | K20: - | L20: =('HDFC IS'!D9-'HDFC IS'!C9)/'HDFC IS'!C9 -> 0.17730428 | M20: =('HDFC IS'!E9-'HDFC IS'!D9)/'HDFC IS'!D9 -> 0.069852852 | N20: HDFC's Net Interest Income grew sharply in FY2025 before slowing in FY2026, while SBI's NII growth has been steadier but more modest across both years.
B21: Growth Ratios | C21: Net Profit Growth | D21: - | E21: =('SBI IS'!D22-'SBI IS'!C22)/'SBI IS'!C22 -> 0.15617092 | F21: =('SBI IS'!E22-'SBI IS'!D22)/'SBI IS'!D22 -> 0.073973059 | I21: Growth Ratios | J21: Net Profit Growth | K21: - | L21: =('HDFC IS'!D21-'HDFC IS'!C21)/'HDFC IS'!C21 -> 0.10505769 | M21: =('HDFC IS'!E21-'HDFC IS'!D21)/'HDFC IS'!D21 -> 0.073930692 | N21: SBI posted stronger Net Profit growth than HDFC in FY2025, though growth decelerated for both banks by FY2026, converging to a similar mid-single-digit pace.
B22: Growth Ratios | C22: Total Asset Growth | D22: - | E22: =('SBI BS'!D24-'SBI BS'!C24)/'SBI BS'!C24 -> 0.086193289 | F22: =('SBI BS'!E24-'SBI BS'!D24)/'SBI BS'!D24 -> 0.13773007 | I22: Growth Ratios | J22: Total Asset Growth | K22: - | L22: =('HDFC BS'!D24-'HDFC BS'!C24)/'HDFC BS'!C24 -> 0.089877345 | M22: =('HDFC BS'!E24-'HDFC BS'!D24)/'HDFC BS'!D24 -> 0.11738944 | N22: SBI's Total Assets grew faster than HDFC's in FY2026, though HDFC posted the faster growth in FY2025; overall balance-sheet expansion has been broadly comparable between the two banks.
B23: Growth Ratios | C23: Net Revenue Growth | D23: - | E23: =('SBI IS'!D11-'SBI IS'!C11)/'SBI IS'!C11 -> 0.082311611 | F23: =('SBI IS'!E11-'SBI IS'!D11)/'SBI IS'!D11 -> 0.097237141 | I23: Growth Ratios | J23: Net Revenue Growth | K23: - | L23: =('HDFC IS'!D11-'HDFC IS'!C11)/'HDFC IS'!C11 -> 0.13064683 | M23: =('HDFC IS'!E11-'HDFC IS'!D11)/'HDFC IS'!D11 -> 0.07995858 | N23: HDFC's Net Revenue growth outpaced SBI's in FY2025, but SBI grew revenue faster in FY2026, again showing the two banks trading places year to year.
B24: Growth Ratios | C24: Operating Income Growth | D24: - | E24: =('SBI IS'!D14-'SBI IS'!C14)/'SBI IS'!C14 -> 0.27168064 | F24: =('SBI IS'!E14-'SBI IS'!D14)/'SBI IS'!D14 -> 0.072813047 | I24: Growth Ratios | J24: Operating Income Growth | K24: - | L24: =('HDFC IS'!D14-'HDFC IS'!C14)/'HDFC IS'!C14 -> 0.086918508 | M24: =('HDFC IS'!E14-'HDFC IS'!D14)/'HDFC IS'!D14 -> 0.16646953 | N24: SBI's Operating Income growth was exceptionally strong in FY2025 before slowing sharply in FY2026, while HDFC shows the opposite pattern — accelerating operating income growth into FY2026.
B25: Growth Ratios | C25: Investment Growth | D25: - | E25: =('SBI BS'!D20-'SBI BS'!C20)/'SBI BS'!C20 -> 0.045037058 | F25: =('SBI BS'!E20-'SBI BS'!D20)/'SBI BS'!D20 -> 0.069777378 | I25: Growth Ratios | J25: Investment Growth | K25: - | L25: =('HDFC BS'!D20-'HDFC BS'!C20)/'HDFC BS'!C20 -> 0.17976987 | M25: =('HDFC BS'!E20-'HDFC BS'!D20)/'HDFC BS'!D20 -> 0.079010149 | N25: HDFC grew its investment book considerably faster than SBI in FY2025, though both banks posted more modest, closer investment growth in FY2026.
B26: Asset Quality | C26: Gross NPA Ratio | D26: 2.24 | E26: 1.82 | F26: 1.49 | I26: Asset Quality | J26: Gross NPA Ratio | K26: 1.24 | L26: 1.33 | M26: 1.15 | N26: HDFC Bank has fewer bad loans compared with SBI, meaning HDFC's loan quality is better.
B27: Asset Quality | C27: Net NPA Ratio | D27: 0.57 | E27: 0.47 | F27: 0.39 | I27: Asset Quality | J27: Net NPA Ratio | K27: 0.33 | L27: 0.43 | M27: 0.38 | N27: HDFC also has fewer bad loans after adjusting for provisions, while SBI has improved significantly over the three years.
B28: Asset Quality | C28: Provision Coverage Ratio | D28: 91.89 | E28: 92.08 | F28: 91.97 | I28: Asset Quality | J28: Provision Coverage Ratio | K28: 74.04 | L28: 67.86 | M28: 67.21 | N28: SBI's Provision Coverage Ratio is significantly higher than HDFC's throughout, meaning SBI has provided for a larger share of its bad loans, which is a more conservative buffer against credit losses.
B29: Capital Adequacy | C29: CET1 Ratio | D29: 10.36 | E29: 10.81 | F29: 12.29 | I29: Capital Adequacy | J29: CET1 Ratio | K29: 16.3 | L29: 17.23 | M29: 17.28 | N29: HDFC's CET1 Ratio is well above SBI's in every year, giving HDFC a thicker core-equity capital cushion, even as SBI's CET1 has been improving steadily.
B30: Capital Adequacy | C30: Tier 1 Ratio | D30: 11.93 | E30: 12.11 | F30: 13.33 | I30: Capital Adequacy | J30: Tier 1 Ratio | K30: 16.79 | L30: 17.69 | M30: 17.73 | N30: HDFC maintains a higher Tier 1 Ratio than SBI across all three years, though SBI's Tier 1 capital position has strengthened noticeably by FY2026.
B31: Capital Adequacy | C31: Tier 2 Ratio | D31: 2.35 | E31: 2.14 | F31: 2.07 | I31: Capital Adequacy | J31: Tier 2 Ratio | K31: 2.01 | L31: 1.86 | M31: 1.98 | N31: Tier 2 Ratios are broadly similar and modest for both banks, with SBI holding a marginally larger Tier 2 cushion than HDFC in most years.
B32: Capital Adequacy | C32: CRAR | D32: 14.28 | E32: 14.25 | F32: 15.4 | I32: Capital Adequacy | J32: CRAR | K32: ='HDFC BS'!C29/'HDFC BS'!C30*100 -> 18.800549 | L32: ='HDFC BS'!D29/'HDFC BS'!D30*100 -> 19.550442 | M32: ='HDFC BS'!E29/'HDFC BS'!E30*100 -> 19.710606 | N32: HDFC's overall Capital to Risk-weighted Assets Ratio (CRAR) is markedly higher than SBI's, underscoring HDFC's stronger overall capital adequacy position.
B33: Capital Adequacy | C33: Leverage Ratio | D33: 5.67 | E33: 6.01 | F33: 6.25 | I33: Capital Adequacy | J33: Leverage Ratio | K33: 10.4 | L33: 10.91 | M33: 10.99 | N33: HDFC's Leverage Ratio is nearly double SBI's, indicating HDFC holds proportionally more Tier 1 capital against its balance sheet size than SBI does.
B34: Efficiency | C34: Cost-to-Income | D34: ='SBI IS'!C13/'SBI IS'!C11 -> 0.7044996 | E34: ='SBI IS'!D13/'SBI IS'!D11 -> 0.65279672 | F34: ='SBI IS'!E13/'SBI IS'!E11 -> 0.66052533 | I34: Efficiency | J34: Cost-to-Income | K34: ='HDFC IS'!C13/'HDFC IS'!C11 -> 0.59982513 | L34: ='HDFC IS'!D13/'HDFC IS'!D11 -> 0.61530209 | M34: ='HDFC IS'!E13/'HDFC IS'!E11 -> 0.58448555 | N34: (Same as Cost-to-Income Ratio above) HDFC continues to operate more efficiently than SBI on a cost-to-revenue basis across all three years.
B35: Efficiency | C35: Asset Utilization | D35: ='SBI IS'!C11/'SBI BS'!C24 -> 0.049725253 | E35: ='SBI IS'!D11/'SBI BS'!D24 -> 0.049547552 | F35: ='SBI IS'!E11/'SBI BS'!E24 -> 0.047784107 | I35: Efficiency | J35: Asset Utilization | K35: ='HDFC IS'!C11/'HDFC BS'!C24 -> 0.062988582 | L35: ='HDFC IS'!D11/'HDFC BS'!D24 -> 0.065344821 | M35: ='HDFC IS'!E11/'HDFC BS'!E24 -> 0.063155868 | N35: HDFC generates more Net Revenue per unit of Total Assets than SBI, consistent with HDFC's higher-yielding, more fee-oriented business mix.
B36: Efficiency | C36: Profit per Employee | D36: =('SBI IS'!C22/'SBI BS'!C32)*100 -> 28.878957 | E36: =('SBI IS'!D22/'SBI BS'!D32)*100 -> 32.833531 | F36: =('SBI IS'!E22/'SBI BS'!E32)*100 -> 33.981335 | I36: Efficiency | J36: Profit per Employee | K36: =('HDFC IS'!C21/'HDFC BS'!C32)*100 -> 30.001845 | L36: =('HDFC IS'!D21/'HDFC BS'!D32)*100 -> 33.000149 | M36: =('HDFC IS'!E21/'HDFC BS'!E32)*100 -> 36.000895 | N36: HDFC generates modestly higher Net Profit per Employee than SBI in every year, though SBI's per-employee profitability has been rising at a faster pace, partly closing the gap by FY2026.

Sheet HDFC IS Forecasting
B1: HDFC Bank Limited
B3: Income Statement Forecast (2024-2029)
B4: INR ( Rupees in Crores)
B5: Line Items | C5: 2024 | D5: 2025 | E5: 2026 | F5: 2027 | G5: 2028 | H5: 2029
B7: Interest Earned | C7: 283649.02 | D7: 336367.43 | E7: 348615.15 | F7: =E7*(1+$C$31) -> 387358.43 | G7: =F7*(1+$C$31) -> 430407.44 | H7: =G7*(1+$C$31) -> 478240.69
B8: Interest Expense | C8: 154138.55 | D8: 183894.2 | E8: 185491.23 | F8: =E8*(1+$C$32) -> 204200.74 | G8: =F8*(1+$C$32) -> 224797.38 | H8: =G8*(1+$C$32) -> 247471.49
B9: Net Interest Income | C9: =C7-C8 -> 129510.47 | D9: =D7-D8 -> 152473.23 | E9: =E7-E8 -> 163123.92 | F9: =F7-F8 -> 183157.69 | G9: =G7-G8 -> 205610.06 | H9: =H7-H8 -> 230769.19
B10: Other Income | C10: 124345.75 | D10: 134548.5 | E10: 146847.66 | F10: =E10*(1+$C$33) -> 159583.91 | G10: =F10*(1+$C$33) -> 173424.79 | H10: =G10*(1+$C$33) -> 188466.1
B11: Net Revenue | C11: =C9+C10 -> 253856.22 | D11: =D9+D10 -> 287021.73 | E11: =E9+E10 -> 309971.58 | F11: =F9+F10 -> 342741.6 | G11: =G9+G10 -> 379034.84 | H11: =H9+H10 -> 419235.29
B13: Operating expenses | C13: 152269.34 | D13: 176605.07 | E13: 181173.91 | F13: =E13*(1+$C$34) -> 197995.06 | G13: =F13*(1+$C$34) -> 216377.98 | H13: =G13*(1+$C$34) -> 236467.67
B14: Operating Income | C14: =C11-C13 -> 101586.88 | D14: =D11-D13 -> 110416.66 | E14: =E11-E13 -> 128797.67 | F14: =F11-F13 -> 144746.54 | G14: =G11-G13 -> 162656.86 | H14: =H11-H13 -> 182767.62
B16: Provisions and contingencies (ex-tax) | C16: 26057.36 | D16: 15845.79 | E16: 29080.81 | F16: =$C$35*'HDFC BS Forecasting'!F21 -> 28230.08 | G16: =$C$35*'HDFC BS Forecasting'!G21 -> 30757.745 | H16: =$C$35*'HDFC BS Forecasting'!H21 -> 33511.731
B17: Net Profit Before Taxation | C17: =C14-C16 -> 75529.52 | D17: =D14-D16 -> 94570.87 | E17: =E14-E16 -> 99716.86 | F17: =F14-F16 -> 116516.46 | G17: =G14-G16 -> 131899.12 | H17: =H14-H16 -> 149255.89
B18: Taxation | C18: 10083.02 | D18: 21130.7 | E18: 20497.4 | F18: =F17*$C$36 -> 21846.504 | G18: =G17*$C$36 -> 24730.71 | H18: =H17*$C$36 -> 27985.056
B19: Net Profit After taxation | C19: =C17-C18 -> 65446.5 | D19: =D17-D18 -> 73440.17 | E19: =E17-E18 -> 79219.46 | F19: =F17-F18 -> 94669.951 | G19: =G17-G18 -> 107168.41 | H19: =H17-H18 -> 121270.84
B20: Less: Minority Interest | C20: 1384.46 | D20: 2647.92 | E20: 3193.49 | F20: =E20*(1+$C$38) -> 3479.2888 | G20: =F20*(1+$C$38) -> 3790.6649 | H20: =G20*(1+$C$38) -> 4129.9074
B21: Net Profit | C21: =C19-C20 -> 64062.04 | D21: =D19-D20 -> 70792.25 | E21: =E19-E20 -> 76025.97 | F21: =F19-F20 -> 91190.662 | G21: =G19-G20 -> 103377.74 | H21: =H19-H20 -> 117140.93
B23: Basic EPS | C23: =(C21)/C24 -> 45.21 | D23: =(D21)/D24 -> 46.404149 | E23: =(E21)/E24 -> 49.504253 | F23: =(F21)/F24 -> 56.73543 | G23: =(G21)/G24 -> 61.454609 | H23: =(H21)/H24 -> 66.536434
B24: Basic Shares | C24: 1416.9883 | D24: 1525.5586 | E24: 1535.7462 | F24: =E24*(1+$C$39) -> 1607.2966 | G24: =F24*(1+$C$39) -> 1682.1805 | H24: =G24*(1+$C$39) -> 1760.5532
B25: Diluted EPS | C25: =(C21)/C26 -> 45.005 | D25: =(D21)/D26 -> 46.197156 | E25: =(E21)/E26 -> 49.278068 | F25: =(F21)/F26 -> 56.73543 | G25: =(G21)/G26 -> 61.454609 | H25: =(H21)/H26 -> 66.536434
B26: Diluted Shares | C26: 1423.4427 | D26: 1532.3941 | E26: 1542.7953 | F26: =F24 -> 1607.2966 | G26: =G24 -> 1682.1805 | H26: =H24 -> 1760.5532
B29: Key Forecast Assumptions (applied 2027-2029)
B30: Driver / Assumption | C30: Value | D30: Basis / Note
B31: Interest Earned growth | C31: =AVERAGE(D7/C7-1,E7/D7-1) -> 0.11113481 | D31: Average YoY growth, FY2024-FY2026
B32: Interest Expense growth | C32: =AVERAGE(D8/C8-1,E8/D8-1) -> 0.10086467 | D32: Average YoY growth, FY2024-FY2026
B33: Other Income growth | C33: =AVERAGE(D10/C10-1,E10/D10-1) -> 0.086731032 | D33: Average YoY growth, FY2024-FY2026
B34: Operating Expenses growth | C34: =AVERAGE(D13/C13-1,E13/D13-1) -> 0.092845334 | D34: Average YoY growth, FY2024-FY2026
B35: Provisions (% of Advances) | C35: =AVERAGE(C16/'HDFC BS Forecasting'!C21,D16/'HDFC BS Forecasting'!D21,E16/'HDFC BS Forecasting'!E21) -> 0.0084929465 | D35: Avg Provisions/Advances FY2024-26; applied to 'SBI BS Forecasting' Advances
B36: Effective Tax Rate | C36: =AVERAGE(C18/C17,D18/D17,E18/E17) -> 0.18749716 | D36: Average effective tax rate (Tax/PBT), FY2024-FY2026
B37: Share in Profit of Associates growth | C37: =AVERAGE(D20/C20-1,E20/D20-1) -> 0.55931925 | D37: Average YoY growth, FY2024-FY2026
B38: Minority Interest growth | C38: =AVERAGE(D21/C21-1,E21/D21-1) -> 0.089494191 | D38: Average YoY growth, FY2024-FY2026
B39: Basic/Diluted Shares growth | C39: =AVERAGE(D25/C25-1,E25/D25-1) -> 0.046589958 | D39: Average YoY growth, FY2024-FY2026

Sheet HDFC BS Forecasting
B1: HDFC Bank Limited
B3: Balance Sheet Forecast (2024-2029)
B4: INR ( Rupees in Crores)
B5: Line Items | C5: 2024 | D5: 2025 | E5: 2026 | F5: 2027 | G5: 2028 | H5: 2029
B7: Capital and Liabilities
B8: Capital | C8: 759.69 | D8: 765.22 | E8: 1539.34 | F8: =E8*(1+$C$31) -> 2323.5644 | G8: =F8*(1+$C$31) -> 3507.3158 | H8: =G8*(1+$C$31) -> 5294.1353
B9: Reserves & Surplus | C9: 452982.84 | D9: 517218.98 | E9: 579975.02 | F9: =E9+'HDFC IS Forecasting'!F22+'HDFC CF Forecasting'!F24+$C$39 -> 642604.56 | G9: =F9+'HDFC IS Forecasting'!G22+'HDFC CF Forecasting'!G24+$C$39 -> 702743.97 | H9: =G9+'HDFC IS Forecasting'!H22+'HDFC CF Forecasting'!H24+$C$39 -> 760071.19
B10: Minority Interest & Other Equity | C10: 16036.12 | D10: 20164.23 | E10: 26930.07 | F10: =E10*(1+$C$32) -> 34914.33 | G10: =F10*(1+$C$32) -> 45265.774 | H10: =G10*(1+$C$32) -> 58686.227
B12: Deposits | C12: 2376887.3 | D12: 2710898.2 | E12: 3099638.3 | F12: =E12*(1+$C$33) -> 3539668.4 | G12: =F12*(1+$C$33) -> 4042165.9 | H12: =G12*(1+$C$33) -> 4615998.9
B13: Borrowings | C13: 730615.46 | D13: 634605.57 | E13: 588484.55 | F13: =E13*(1+$C$34) -> 528433.74 | G13: =F13*(1+$C$34) -> 474510.7 | H13: =G13*(1+$C$34) -> 426090.14
B14: Other Liabilities and Provisions | C14: 452912.87 | D14: 508765.19 | E14: 611473.57 | F14: =F24-(F8+F9+F10+F12+F13) -> 711647.57 | G14: =G24-(G8+G9+G10+G12+G13) -> 753648.28 | H14: =H24-(H8+H9+H10+H12+H13) -> 830999.93
B15: Total Capital and Liabilities | C15: =SUM(C8:C14) -> 4030194.3 | D15: =SUM(D8:D14) -> 4392417.4 | E15: =SUM(E8:E14) -> 4908040.8 | F15: =SUM(F8:F14) -> 5459592.2 | G15: =SUM(G8:G14) -> 6021841.9 | H15: =SUM(H8:H14) -> 6697140.5
B17: Assets
B18: Cash and Balances with Reserve Bank of India | C18: 178718.67 | D18: 144390.25 | E18: 200707.11 | F18: ='HDFC CF Forecasting'!F32-F19 -> 227783.08 | G18: ='HDFC CF Forecasting'!G32-G19 -> 169403.87 | H18: ='HDFC CF Forecasting'!H32-H19 -> 112168.33
B19: Balances with Banks and Money at Call & Short Notice | C19: 50115.84 | D19: 105557.65 | E19: 111218.94 | F19: =E19*(1+$C$35) -> 175720.66 | G19: =F19*(1+$C$35) -> 277630.34 | H19: =G19*(1+$C$35) -> 438642.8
B20: Investments | C20: 1005681.6 | D20: 1186472.9 | E20: 1280216.3 | F20: =E20*(1+$C$36) -> 1445863.5 | G20: =F20*(1+$C$36) -> 1632943.8 | H20: =G20*(1+$C$36) -> 1844230.4
B21: Advances | C21: 2571916.6 | D21: 2724938.2 | E21: 3050783.2 | F21: =E21*(1+$C$37) -> 3323944.2 | G21: =F21*(1+$C$37) -> 3621563.4 | H21: =G21*(1+$C$37) -> 3945830.9
B22: Fixed Assets | C22: 12603.76 | D22: 15257.94 | E22: 16491.59 | F22: =E22-'HDFC CF Forecasting'!F19-'HDFC CF Forecasting'!F9 -> 16015.975 | G22: =F22-'HDFC CF Forecasting'!G19-'HDFC CF Forecasting'!G9 -> 26510.987 | H22: =G22-'HDFC CF Forecasting'!H19-'HDFC CF Forecasting'!H9 -> 36906.067
B23: Other Assets | C23: 211157.71 | D23: 215800.53 | E23: 248623.68 | F23: =E23*(1+$C$38) -> 270264.75 | G23: =F23*(1+$C$38) -> 293789.53 | H23: =G23*(1+$C$38) -> 319361.99
B24: Total Assets | C24: =SUM(C17:C23) -> 4030194.3 | D24: =SUM(D17:D23) -> 4392417.4 | E24: =SUM(E17:E23) -> 4908040.8 | F24: =SUM(F17:F23) -> 5459592.2 | G24: =SUM(G17:G23) -> 6021841.9 | H24: =SUM(H17:H23) -> 6697140.5
B26: Balance Check (Total Assets − Total Capital & Liabilities) | C26: =C24-C15 -> 0 | D26: =D24-D15 -> 0 | E26: =E24-E15 -> 0 | F26: =F24-F15 -> 0 | G26: =G24-G15 -> 0 | H26: =H24-H15 -> 0
B29: Key Forecast Assumptions (applied 2027-2029)
B30: Driver / Assumption | C30: Value | D30: Basis / Note
B31: Capital growth | C31: =AVERAGE(D8/C8-1,E8/D8-1) -> 0.50945496 | D31: Formula: avg YoY growth, FY2024-FY2026 (row 8)
B32: Minority Interest & Other Equity growth | C32: =AVERAGE(D10/C10-1,E10/D10-1) -> 0.29648124 | D32: Formula: avg YoY growth, FY2024-FY2026 (row 10)
B33: Deposits growth | C33: =AVERAGE(D12/C12-1,E12/D12-1) -> 0.14196175 | D33: Formula: avg YoY growth, FY2024-FY2026 (row 12)
B34: Borrowings growth | C34: =AVERAGE(D13/C13-1,E13/D13-1) -> -0.10204314 | D34: Formula: avg YoY growth, FY2024-FY2026 (row 13)
B35: Balances with Banks & Money at Call growth | C35: =AVERAGE(D19/C19-1,E19/D19-1) -> 0.5799527 | D35: Formula: avg YoY growth, FY2024-FY2026 (row 19)
B36: Investments growth | C36: =AVERAGE(D20/C20-1,E20/D20-1) -> 0.12939001 | D36: Formula: avg YoY growth, FY2024-FY2026 (row 20)
B37: Advances growth | C37: =AVERAGE(D21/C21-1,E21/D21-1) -> 0.089537979 | D37: Formula: avg YoY growth, FY2024-FY2026 (row 21)
B38: Other Assets growth | C38: =AVERAGE(D23/C23-1,E23/D23-1) -> 0.08704347 | D38: Formula: avg YoY growth, FY2024-FY2026 (row 23)
B39: Other Reserve Movements (Rs Cr, flat p.a.) | C39: =AVERAGE((D9-C9)-('HDFC IS Forecasting'!D22+'HDFC CF Forecasting'!D24),(E9-D9)-('HDFC IS Forecasting'!E22+'HDFC CF Forecasting'!E24)) -> 81262.175 | D39: Formula: AVERAGE of (actual reserve change less Net Profit less Dividends) for FY2025 and FY2026 - captures OCI/associate equity pickup etc. not modeled elsewhere
B40: Other Liabilities and Provisions | C40: Plug | D40: Balancing item = Total Assets less all other liabilities & equity, so the Balance Sheet ties out exactly each forecast year

Sheet HDFC CF Forecasting
B1: HDFC Bank Limited
B3: Cash Flow Forecast (2024-2029)
B4: INR ( Rupees in Crores)
B5: Line Items | C5: 2024 | D5: 2025 | E5: 2026 | F5: 2027 | G5: 2028 | H5: 2029
B7: Cash Flow From Operating Activites
B8: Net Profit/(Loss) before taxes (including share in profit from associates and net of minority interest) | C8: ='HDFC IS'!C21+'HDFC IS'!C18+'HDFC IS'!C20-345.38 -> 75184.14 | D8: ='HDFC IS'!D21+'HDFC IS'!D18+'HDFC IS'!D20-976.74 -> 93594.13 | E8: ='HDFC IS'!E21+'HDFC IS'!E18+'HDFC IS'!E20-768.9 -> 98947.96 | F8: ='HDFC IS Forecasting'!F17+'HDFC IS Forecasting'!F20 -> 119995.74 | G8: ='HDFC IS Forecasting'!G17+'HDFC IS Forecasting'!G20 -> 135689.78 | H8: ='HDFC IS Forecasting'!H17+'HDFC IS Forecasting'!H20 -> 153385.8
B9: Depreciation on Fixed Assets | C9: 3092.08 | D9: 3805.23 | E9: 4194.9 | F9: =E9*(1+$C$37) -> 4893.4377 | G9: =F9*(1+$C$37) -> 5708.2965 | H9: =G9*(1+$C$37) -> 6658.8461
B10: Other Operating Activities | C10: 13342.18 | D10: 20242.8 | E10: 30402.47 | F10: =$C$38*'HDFC IS Forecasting'!F11 -> 25267.66 | G10: =$C$38*'HDFC IS Forecasting'!G11 -> 27943.277 | H10: =$C$38*'HDFC IS Forecasting'!H11 -> 30906.942
B11: Tax refund / (Taxes paid) | C11: -22842.84 | D11: 29308.36 | E11: -22656.37 | F11: =E11*(1+$C$39) -> 23291.632 | G11: =F11*(1+$C$39) -> -23944.706 | H11: =G11*(1+$C$39) -> 24616.092
B12: Change in Net Working Capital | C12: -49706.22 | D12: -19708.68 | E12: 2617.42 | F12: =$C$40*'HDFC BS Forecasting'!F21 -> -28476.546 | G12: =$C$40*'HDFC BS Forecasting'!G21 -> -31026.279 | H12: =$C$40*'HDFC BS Forecasting'!H21 -> -33804.309
B14: Total Cash Flow From Operating Activites | C14: =C8+C9+C1+C10+C11+C12 -> 19069.34 | D14: =D8+D9+D1+D10+D11+D12 -> 127241.84 | E14: =E8+E9+E1+E10+E11+E12 -> 113506.38 | F14: =SUM(F8:F12) -> 144971.93 | G14: =SUM(G8:G12) -> 114370.37 | H14: =SUM(H8:H12) -> 181763.37
B16: Cash Flow From Investing Activites
B17: Purchase of Investments | C17: - | D17: - | E17: - | F17: - | G17: - | H17: -
B18: Sale Of Investments | C18: 9500.67 | D18: 192 | E18: 9806 | F18: =E18*(1+$C$41) -> 11074.798 | G18: =F18*(1+$C$41) -> 12507.767 | H18: =G18*(1+$C$41) -> 14126.147
B19: Purchase and Sale of Fixed Assets | C19: -4186.9 | D19: -3975.17 | E19: -3362.41 | F19: =-$C$42*'HDFC BS Forecasting'!E22 -> -4417.8226 | G19: =-$C$42*'SBI BS Forecasting'!F22 -> -16203.309 | H19: =-$C$42*'SBI BS Forecasting'!G22 -> -17053.925
B20: Income from Investments in Associates | C20: - | D20: -67.47 | E20: -80.87 | F20: =$C$43 -> -80.87 | G20: =$C$43 -> -80.87 | H20: =$C$43 -> -80.87
B21: Total Cash Flow From Investing Activites | C21: =SUM(C17:C20) -> 5313.77 | D21: =SUM(D17:D20) -> -3850.64 | E21: =SUM(E17:E20) -> 6362.72 | F21: =SUM(F17:F20) -> 6576.1058 | G21: =SUM(G17:G20) -> -3776.4123 | H21: =SUM(H17:H20) -> -3008.6485
B23: Cash Flow From Financing Activites
B24: Dividend paid | C24: -8404.42 | D24: -14826.19 | E24: -20705.98 | F24: =-$C$44*'HDFC IS Forecasting'!F21 -> -18632.633 | G24: =-$C$44*'HDFC IS Forecasting'!G21 -> -21122.772 | H24: =-$C$44*'HDFC IS Forecasting'!H21 -> -23934.95
B25: Other Financing Activities | C25: 4421.36 | D25: -87651.35 | E25: -38298.87 | F25: =E25*(1+$C$45) -> -42451.607 | G25: =F25*(1+$C$45) -> -47054.624 | H25: =G25*(1+$C$45) -> -52156.744
B26: Total Cash Flow From Financing Activites | C26: =SUM(C24:C25) -> -3983.06 | D26: =SUM(D24:D25) -> -102477.54 | E26: =SUM(E24:E25) -> -59004.85 | F26: =SUM(F24:F25) -> -61084.24 | G26: =SUM(G24:G25) -> -68177.395 | H26: =SUM(H24:H25) -> -76091.694
B28: Effect of fluctuation in foreign currency translation reserve | C28: 104.94 | D28: 199.73 | E28: 1113.9 | F28: =$C$46 -> 1113.9 | G28: =$C$46 -> 1113.9 | H28: =$C$46 -> 1113.9
B29: Net Change in Cash | C29: =C14+C21+C26+C28 -> 20504.99 | D29: =D14+D21+D26+D28 -> 21113.39 | E29: =E14+E21+E26+E28 -> 61978.15 | F29: =F14+F21+F26+F28 -> 91577.694 | G29: =G14+G21+G26+G28 -> 43530.464 | H29: =H14+H21+H26+H28 -> 103776.93
B31: Cash and cash equivalents at the beginning of the year | C31: 208329.52 | D31: ='HDFC BS'!C18+'HDFC BS'!C19 -> 228834.51 | E31: ='HDFC BS'!D18+'HDFC BS'!D19 -> 249947.9 | F31: ='HDFC BS Forecasting'!E18+'HDFC BS Forecasting'!E19 -> 311926.05 | G31: ='HDFC BS Forecasting'!F18+'HDFC BS Forecasting'!F19 -> 403503.74 | H31: ='HDFC BS Forecasting'!G18+'HDFC BS Forecasting'!G19 -> 447034.21
B32: Cash and cash equivalents at the end of the year | C32: =C29+C31 -> 228834.51 | D32: =D31+D29 -> 249947.9 | E32: =E31+E29 -> 311926.05 | F32: =F31+F29 -> 403503.74 | G32: =G31+G29 -> 447034.21 | H32: =H31+H29 -> 550811.14
B35: Key Forecast Assumptions (applied 2027-2029)
B36: Driver / Assumption | C36: Value | D36: Basis / Note
B37: Depreciation growth | C37: =AVERAGE(D9/C9-1,E9/D9-1) -> 0.16652071 | D37: Formula: avg YoY growth, FY2024-FY2026 (row 9)
